Workbook
Name beta0: [1]DemandProfitPrediction!$E$2
Name capacity: DemandPredictionModel!$C$23
Name cost: [1]DemandProfitPrediction!$B$2
Name demand: DemandPredictionModel!$C$30
Name exp_vc: [1]DemandProfitPrediction!$I$8
Name fixedCost: DemandPredictionModel!$C$21
Name marginalCost: DemandPredictionModel!$C$22
Name market: [1]DemandProfitPrediction!$E$6
Name marketSize: DemandPredictionModel!$C$17
Name price: DemandPredictionModel!$C$31
Name profit: DemandPredictionModel!$C$33
Name revenue: DemandPredictionModel!$C$32
Name riskTolerance: Utility!$C$1
Name utility: Utility!$C$3
Name xin1: DemandPredictionModel!$C$24
Name xin2: DemandPredictionModel!$C$25
Name xin3: DemandPredictionModel!$C$26

Sheet Introduction
A1: Introduction to the Project and Survey
A3: In this survey, you will be asked to express your preferences about a new portable electric kettle under design. The new kettle is targeted for the general public but some key potential customers include people working at construction sites, camping or spending time outdoors. If your preference would be influenced by attributes not specified in the survey, assume kettle characteristics similar to these comparable vehicles. You will be asked to focus on four specific attributes of the new kettle. System context and details of each attribute are listed below. Please review the information on this tab/page, then proceed to the Survey tab to complete the survey. NOTE: Please find your Student Number on the "Roster" tab and then enter your number in the Survey Number cell of the "Survey" tab. This step is necessary to enable the survey. Otherwise you will not be able to complete the survey.
A5: Some Details About the System
A7: The purpose of the Portable Electric Kettle (PEK) is to bring fluid to a boil without the need for a wall outlet for power. The PEK utilizes an on board heating element to pull power from an internal battery bank to bring fluid to a boil. The kettle is vacuum insulated with an insulated lid to provide efficient heating. The kettle has multiple temperature settings, allowing the operator to select the appropriate temperature according to his or her preference.
A9: Assumptions
A11: The outer diameter of the kettle will be no larger than a Nalgene (3.5in) The kettle will be charged with a PD USB-C cable. The unit will be capable of being charged from empty to full in less than 3 hours.
A13: Attributes Appearing in the Survey
A14: Attribute Name | B14: Units | C14: Low | D14: Medium | E14: High | F14: Description
A15: =SurveySetup!A3 -> price | B15: =SurveySetup!B3 -> $ | C15: =SurveySetup!C3 -> 50 | D15: =SurveySetup!D3 -> 100 | E15: =SurveySetup!E3 -> 200 | F15: The price of the kettle
A16: =SurveySetup!A4 -> Fluid Capacity | B16: =SurveySetup!B4 -> liters | C16: =SurveySetup!C4 -> 0.25 | D16: =SurveySetup!D4 -> 1 | E16: =SurveySetup!E4 -> 2 | F16: The total fluid the kettle can boil at a time
A17: =SurveySetup!A5 -> Time to boil | B17: =SurveySetup!B5 -> sec | C17: =SurveySetup!C5 -> 120 | D17: =SurveySetup!D5 -> 240 | E17: =SurveySetup!E5 -> 600 | F17: The time it takes for the kettle to boil the maximum fluid capacity at sea level
A18: =SurveySetup!A6 -> Boils per charge | B18: =SurveySetup!B6 -> # | C18: =SurveySetup!C6 -> 1 | D18: =SurveySetup!D6 -> 5 | E18: =SurveySetup!E6 -> 10 | F18: The number of full boils the kettle can achieve on a single charge

Sheet Roster
A1: Roster with Survey ID Assignments
A2: Survey ID# | B2: Student Name | C2: E-mail
A3: 1 | B3: Abdirizak, Miski A | C3: mabdirizak3@gatech.edu
A4: 2 | B4: Adhikari, Samrat | C4: sadhikari65@gatech.edu
A5: 3 | B5: Adhikary, Meghan Turie | C5: madhikary3@gatech.edu
A6: 4 | B6: Aghamyan, Arman | C6: aaghamyan3@gatech.edu
A7: 5 | B7: Alarcon Chavez, Andros | C7: androsac@gatech.edu
A8: 6 | B8: Alcocer, Jathzel | C8: jalcocer3@gatech.edu
A9: 7 | B9: Alcorn-Ferrell, Nyra' Tyrie | C9: nta31@gatech.edu
A10: 8 | B10: Bailey, Michael Scott | C10: mbailey44@gatech.edu
A11: 9 | B11: Boman, Alex S | C11: aboman3@gatech.edu
A12: 10 | B12: Brown, Destiny S | C12: dbrown469@gatech.edu
A13: 11 | B13: Bundu, Zainab | C13: zbundu3@gatech.edu
A14: 12 | B14: Calimlim, Luke | C14: lcalimlim3@gatech.edu
... A65: 63 | B65: Zomiti, Wajdi | C65: wajdi.zomiti@gatech.edu

Sheet Survey
A1: Survey number: | B1: 9 | C1: =IF(COUNTIF(J:J,0)=1,"Survey Complete","SURVEY INCOMPLETE--Revisit questions marked:") -> Survey Complete | J1: =IF(COUNTIF(J11:J127,0)=0,1,0) -> 1
A3: Attribute Name | B3: Units | C3: Preference Direction | D3: Low | E3: Medium | F3: High | K3: green | L3: red
A4: =SurveySetup!A3 -> price | B4: =SurveySetup!B3 -> $ | C4: less is better | D4: =SurveySetup!C3 -> 50 | E4: =SurveySetup!D3 -> 100 | F4: =SurveySetup!E3 -> 200 | K4: =IF(C4="less is better",MIN(D4:F4),MAX(D4:F4)) -> 50 | L4: =IF(C4="more is better",MIN(D4:F4),MAX(D4:F4)) -> 200
A5: =SurveySetup!A4 -> Fluid Capacity | B5: =SurveySetup!B4 -> liters | C5: more is better | D5: =SurveySetup!C4 -> 0.25 | E5: =SurveySetup!D4 -> 1 | F5: =SurveySetup!E4 -> 2 | K5: =IF(C5="less is better",MIN(D5:F5),MAX(D5:F5)) -> 2 | L5: =IF(C5="more is better",MIN(D5:F5),MAX(D5:F5)) -> 0.25
A6: =SurveySetup!A5 -> Time to boil | B6: =SurveySetup!B5 -> sec | C6: less is better | D6: =SurveySetup!C5 -> 120 | E6: =SurveySetup!D5 -> 240 | F6: =SurveySetup!E5 -> 600 | K6: =IF(C6="less is better",MIN(D6:F6),MAX(D6:F6)) -> 120 | L6: =IF(C6="more is better",MIN(D6:F6),MAX(D6:F6)) -> 600
A7: =SurveySetup!A6 -> Boils per charge | B7: =SurveySetup!B6 -> # | C7: more is better | D7: =SurveySetup!C6 -> 1 | E7: =SurveySetup!D6 -> 5 | F7: =SurveySetup!E6 -> 10 | K7: =IF(C7="less is better",MIN(D7:F7),MAX(D7:F7)) -> 10 | L7: =IF(C7="more is better",MIN(D7:F7),MAX(D7:F7)) -> 1
A9: Question
A10: 1 | B10: =DOE!$B$2 -> price ($) | C10: =DOE!$C$2 -> Fluid Capacity (liters) | D10: =DOE!$D$2 -> Time to boil (sec) | E10: =DOE!$E$2 -> Boils per charge (#) | F10: Choice (mark with "1") | G10: Alt ID | M10: dominated? | N10: =B10 -> price ($) | O10: =C10 -> Fluid Capacity (liters) | P10: =D10 -> Time to boil (sec) | Q10: =E10 -> Boils per charge (#)
A11: Option 1 | B11: =INDEX(DOE!$A$4:$E$84,$G11,COLUMN(B:B)) -> 200 | C11: =INDEX(DOE!$A$4:$E$84,$G11,COLUMN(C:C)) -> 0.25 | D11: =INDEX(DOE!$A$4:$E$84,$G11,COLUMN(D:D)) -> 120 | E11: =INDEX(DOE!$A$4:$E$84,$G11,COLUMN(E:E)) -> 1 | G11: =INDEX(StaticRandomNumbers!$A$4:$BJ$93,A10*3-2,$B$1+1) -> 55 | H11: =F11*G11 -> 0 | J11: =IF(AND(COUNTIF(F11:F13,"")=2,COUNTIF(F11:F13,1)=1),1,0) -> 1 | M11: =OR(AND(N11>=N12,O11>=O12,P11>=P12,Q11>=Q12),AND(N11>=N13,O11>=O13,P11>=P13,Q11>=Q13)) -> TRUE | N11: =IF(B11=$K$4,1,IF(B11=$L$4,3,2)) -> 3 | O11: =IF(C11=$K$5,1,IF(C11=$L$5,3,2)) -> 3 | P11: =IF(D11=$K$6,1,IF(D11=$L$6,3,2)) -> 1 | Q11: =IF(E11=$K$7,1,IF(E11=$L$7,3,2)) -> 3
A12: Option 2 | B12: =INDEX(DOE!$A$4:$E$84,$G12,COLUMN(B:B)) -> 50 | C12: =INDEX(DOE!$A$4:$E$84,$G12,COLUMN(C:C)) -> 0.25 | D12: =INDEX(DOE!$A$4:$E$84,$G12,COLUMN(D:D)) -> 600 | E12: =INDEX(DOE!$A$4:$E$84,$G12,COLUMN(E:E)) -> 1 | G12: =INDEX(StaticRandomNumbers!$A$4:$BJ$93,A10*3-1,$B$1+1) -> 7 | H12: =F12*G12 -> 0 | M12: =OR(AND(N11<=N12,O11<=O12,P11<=P12,Q11<=Q12),AND(N12>=N13,O12>=O13,P12>=P13,Q12>=Q13)) -> TRUE | N12: =IF(B12=$K$4,1,IF(B12=$L$4,3,2)) -> 1 | O12: =IF(C12=$K$5,1,IF(C12=$L$5,3,2)) -> 3 | P12: =IF(D12=$K$6,1,IF(D12=$L$6,3,2)) -> 3 | Q12: =IF(E12=$K$7,1,IF(E12=$L$7,3,2)) -> 3
A13: Option 3 | B13: =INDEX(DOE!$A$4:$E$84,$G13,COLUMN(B:B)) -> 50 | C13: =INDEX(DOE!$A$4:$E$84,$G13,COLUMN(C:C)) -> 2 | D13: =INDEX(DOE!$A$4:$E$84,$G13,COLUMN(D:D)) -> 120 | E13: =INDEX(DOE!$A$4:$E$84,$G13,COLUMN(E:E)) -> 10 | F13: 1 | G13: =INDEX(StaticRandomNumbers!$A$4:$BJ$93,A10*3,$B$1+1) -> 21 | H13: =F13*G13 -> 21 | M13: =OR(AND(N13>=N12,O13>=O12,P13>=P12,Q13>=Q12),AND(N13>=N11,O13>=O11,P13>=P11,Q13>=Q11)) -> FALSE | N13: =IF(B13=$K$4,1,IF(B13=$L$4,3,2)) -> 1 | O13: =IF(C13=$K$5,1,IF(C13=$L$5,3,2)) -> 1 | P13: =IF(D13=$K$6,1,IF(D13=$L$6,3,2)) -> 1 | Q13: =IF(E13=$K$7,1,IF(E13=$L$7,3,2)) -> 1
A15: Question
A16: =A10+1 -> 2 | B16: =DOE!$B$2 -> price ($) | C16: =DOE!$C$2 -> Fluid Capacity (liters) | D16: =DOE!$D$2 -> Time to boil (sec) | E16: =DOE!$E$2 -> Boils per charge (#) | F16: Choice (mark with "1") | G16: Alt ID | M16: dominated? | N16: =B16 -> price ($) | O16: =C16 -> Fluid Capacity (liters) | P16: =D16 -> Time to boil (sec) | Q16: =E16 -> Boils per charge (#)
A17: Option 1 | B17: =INDEX(DOE!$A$4:$E$84,$G17,COLUMN(B:B)) -> 200 | C17: =INDEX(DOE!$A$4:$E$84,$G17,COLUMN(C:C)) -> 1 | D17: =INDEX(DOE!$A$4:$E$84,$G17,COLUMN(D:D)) -> 120 | E17: =INDEX(DOE!$A$4:$E$84,$G17,COLUMN(E:E)) -> 10 | F17: 1 | G17: =INDEX(StaticRandomNumbers!$A$4:$BJ$93,A16*3-2,$B$1+1) -> 66 | H17: =F17*G17 -> 66 | J17: =IF(AND(COUNTIF(F17:F19,"")=2,COUNTIF(F17:F19,1)=1),1,0) -> 1 | M17: =OR(AND(N17>=N18,O17>=O18,P17>=P18,Q17>=Q18),AND(N17>=N19,O17>=O19,P17>=P19,Q17>=Q19)) -> FALSE | N17: =IF(B17=$K$4,1,IF(B17=$L$4,3,2)) -> 3 | O17: =IF(C17=$K$5,1,IF(C17=$L$5,3,2)) -> 2 | P17: =IF(D17=$K$6,1,IF(D17=$L$6,3,2)) -> 1 | Q17: =IF(E17=$K$7,1,IF(E17=$L$7,3,2)) -> 1
A18: Option 2 | B18: =INDEX(DOE!$A$4:$E$84,$G18,COLUMN(B:B)) -> 50 | C18: =INDEX(DOE!$A$4:$E$84,$G18,COLUMN(C:C)) -> 0.25 | D18: =INDEX(DOE!$A$4:$E$84,$G18,COLUMN(D:D)) -> 600 | E18: =INDEX(DOE!$A$4:$E$84,$G18,COLUMN(E:E)) -> 5 | G18: =INDEX(StaticRandomNumbers!$A$4:$BJ$93,A16*3-1,$B$1+1) -> 8 | H18: =F18*G18 -> 0 | M18: =OR(AND(N17<=N18,O17<=O18,P17<=P18,Q17<=Q18),AND(N18>=N19,O18>=O19,P18>=P19,Q18>=Q19)) -> FALSE | N18: =IF(B18=$K$4,1,IF(B18=$L$4,3,2)) -> 1 | O18: =IF(C18=$K$5,1,IF(C18=$L$5,3,2)) -> 3 | P18: =IF(D18=$K$6,1,IF(D18=$L$6,3,2)) -> 3 | Q18: =IF(E18=$K$7,1,IF(E18=$L$7,3,2)) -> 2
A19: Option 3 | B19: =INDEX(DOE!$A$4:$E$84,$G19,COLUMN(B:B)) -> 200 | C19: =INDEX(DOE!$A$4:$E$84,$G19,COLUMN(C:C)) -> 1 | D19: =INDEX(DOE!$A$4:$E$84,$G19,COLUMN(D:D)) -> 600 | E19: =INDEX(DOE!$A$4:$E$84,$G19,COLUMN(E:E)) -> 5 | G19: =INDEX(StaticRandomNumbers!$A$4:$BJ$93,A16*3,$B$1+1) -> 71 | H19: =F19*G19 -> 0 | M19: =OR(AND(N19>=N18,O19>=O18,P19>=P18,Q19>=Q18),AND(N19>=N17,O19>=O17,P19>=P17,Q19>=Q17)) -> TRUE | N19: =IF(B19=$K$4,1,IF(B19=$L$4,3,2)) -> 3 | O19: =IF(C19=$K$5,1,IF(C19=$L$5,3,2)) -> 2 | P19: =IF(D19=$K$6,1,IF(D19=$L$6,3,2)) -> 3 | Q19: =IF(E19=$K$7,1,IF(E19=$L$7,3,2)) -> 2
A21: Question
A22: =A16+1 -> 3 | B22: =DOE!$B$2 -> price ($) | C22: =DOE!$C$2 -> Fluid Capacity (liters) | D22: =DOE!$D$2 -> Time to boil (sec) | E22: =DOE!$E$2 -> Boils per charge (#) | F22: Choice (mark with "1") | G22: Alt ID | M22: dominated? | N22: =B22 -> price ($) | O22: =C22 -> Fluid Capacity (liters) | P22: =D22 -> Time to boil (sec) | Q22: =E22 -> Boils per charge (#)
A23: Option 1 | B23: =INDEX(DOE!$A$4:$E$84,$G23,COLUMN(B:B)) -> 50 | C23: =INDEX(DOE!$A$4:$E$84,$G23,COLUMN(C:C)) -> 0.25 | D23: =INDEX(DOE!$A$4:$E$84,$G23,COLUMN(D:D)) -> 120 | E23: =INDEX(DOE!$A$4:$E$84,$G23,COLUMN(E:E)) -> 1 | G23: =INDEX(StaticRandomNumbers!$A$4:$BJ$93,A22*3-2,$B$1+1) -> 1 | H23: =F23*G23 -> 0 | J23: =IF(AND(COUNTIF(F23:F25,"")=2,COUNTIF(F23:F25,1)=1),1,0) -> 1 | M23: =OR(AND(N23>=N24,O23>=O24,P23>=P24,Q23>=Q24),AND(N23>=N25,O23>=O25,P23>=P25,Q23>=Q25)) -> FALSE | N23: =IF(B23=$K$4,1,IF(B23=$L$4,3,2)) -> 1 | O23: =IF(C23=$K$5,1,IF(C23=$L$5,3,2)) -> 3 | P23: =IF(D23=$K$6,1,IF(D23=$L$6,3,2)) -> 1 | Q23: =IF(E23=$K$7,1,IF(E23=$L$7,3,2)) -> 3
A24: Option 2 | B24: =INDEX(DOE!$A$4:$E$84,$G24,COLUMN(B:B)) -> 50 | C24: =INDEX(DOE!$A$4:$E$84,$G24,COLUMN(C:C)) -> 1 | D24: =INDEX(DOE!$A$4:$E$84,$G24,COLUMN(D:D)) -> 600 | E24: =INDEX(DOE!$A$4:$E$84,$G24,COLUMN(E:E)) -> 5 | G24: =INDEX(StaticRandomNumbers!$A$4:$BJ$93,A22*3-1,$B$1+1) -> 17 | H24: =F24*G24 -> 0 | M24: =OR(AND(N23<=N24,O23<=O24,P23<=P24,Q23<=Q24),AND(N24>=N25,O24>=O25,P24>=P25,Q24>=Q25)) -> TRUE | N24: =IF(B24=$K$4,1,IF(B24=$L$4,3,2)) -> 1 | O24: =IF(C24=$K$5,1,IF(C24=$L$5,3,2)) -> 2 | P24: =IF(D24=$K$6,1,IF(D24=$L$6,3,2)) -> 3 | Q24: =IF(E24=$K$7,1,IF(E24=$L$7,3,2)) -> 2
A25: Option 3 | B25: =INDEX(DOE!$A$4:$E$84,$G25,COLUMN(B:B)) -> 50 | C25: =INDEX(DOE!$A$4:$E$84,$G25,COLUMN(C:C)) -> 2 | D25: =INDEX(DOE!$A$4:$E$84,$G25,COLUMN(D:D)) -> 600 | E25: =INDEX(DOE!$A$4:$E$84,$G25,COLUMN(E:E)) -> 5 | F25: 1 | G25: =INDEX(StaticRandomNumbers!$A$4:$BJ$93,A22*3,$B$1+1) -> 26 | H25: =F25*G25 -> 26 | M25: =OR(AND(N25>=N24,O25>=O24,P25>=P24,Q25>=Q24),AND(N25>=N23,O25>=O23,P25>=P23,Q25>=Q23)) -> FALSE | N25: =IF(B25=$K$4,1,IF(B25=$L$4,3,2)) -> 1 | O25: =IF(C25=$K$5,1,IF(C25=$L$5,3,2)) -> 1 | P25: =IF(D25=$K$6,1,IF(D25=$L$6,3,2)) -> 3 | Q25: =IF(E25=$K$7,1,IF(E25=$L$7,3,2)) -> 2
A27: Question
A28: =A22+1 -> 4 | B28: =DOE!$B$2 -> price ($) | C28: =DOE!$C$2 -> Fluid Capacity (liters) | D28: =DOE!$D$2 -> Time to boil (sec) | E28: =DOE!$E$2 -> Boils per charge (#) | F28: Choice (mark with "1") | G28: Alt ID | M28: dominated? | N28: =B28 -> price ($) | O28: =C28 -> Fluid Capacity (liters) | P28: =D28 -> Time to boil (sec) | Q28: =E28 -> Boils per charge (#)
A29: Option 1 | B29: =INDEX(DOE!$A$4:$E$84,$G29,COLUMN(B:B)) -> 50 | C29: =INDEX(DOE!$A$4:$E$84,$G29,COLUMN(C:C)) -> 2 | D29: =INDEX(DOE!$A$4:$E$84,$G29,COLUMN(D:D)) -> 600 | E29: =INDEX(DOE!$A$4:$E$84,$G29,COLUMN(E:E)) -> 5 | G29: =INDEX(StaticRandomNumbers!$A$4:$BJ$93,A28*3-2,$B$1+1) -> 26 | H29: =F29*G29 -> 0 | J29: =IF(AND(COUNTIF(F29:F31,"")=2,COUNTIF(F29:F31,1)=1),1,0) -> 1 | M29: =OR(AND(N29>=N30,O29>=O30,P29>=P30,Q29>=Q30),AND(N29>=N31,O29>=O31,P29>=P31,Q29>=Q31)) -> FALSE | N29: =IF(B29=$K$4,1,IF(B29=$L$4,3,2)) -> 1 | O29: =IF(C29=$K$5,1,IF(C29=$L$5,3,2)) -> 1 | P29: =IF(D29=$K$6,1,IF(D29=$L$6,3,2)) -> 3 | Q29: =IF(E29=$K$7,1,IF(E29=$L$7,3,2)) -> 2
A30: Option 2 | B30: =INDEX(DOE!$A$4:$E$84,$G30,COLUMN(B:B)) -> 100 | C30: =INDEX(DOE!$A$4:$E$84,$G30,COLUMN(C:C)) -> 1 | D30: =INDEX(DOE!$A$4:$E$84,$G30,COLUMN(D:D)) -> 120 | E30: =INDEX(DOE!$A$4:$E$84,$G30,COLUMN(E:E)) -> 1 | F30: 1 | G30: =INDEX(StaticRandomNumbers!$A$4:$BJ$93,A28*3-1,$B$1+1) -> 37 | H30: =F30*G30 -> 37 | M30: =OR(AND(N29<=N30,O29<=O30,P29<=P30,Q29<=Q30),AND(N30>=N31,O30>=O31,P30>=P31,Q30>=Q31)) -> FALSE | N30: =IF(B30=$K$4,1,IF(B30=$L$4,3,2)) -> 2 | O30: =IF(C30=$K$5,1,IF(C30=$L$5,3,2)) -> 2 | P30: =IF(D30=$K$6,1,IF(D30=$L$6,3,2)) -> 1 | Q30: =IF(E30=$K$7,1,IF(E30=$L$7,3,2)) -> 3
A31: Option 3 | B31: =INDEX(DOE!$A$4:$E$84,$G31,COLUMN(B:B)) -> 50 | C31: =INDEX(DOE!$A$4:$E$84,$G31,COLUMN(C:C)) -> 0.25 | D31: =INDEX(DOE!$A$4:$E$84,$G31,COLUMN(D:D)) -> 240 | E31: =INDEX(DOE!$A$4:$E$84,$G31,COLUMN(E:E)) -> 5 | G31: =INDEX(StaticRandomNumbers!$A$4:$BJ$93,A28*3,$B$1+1) -> 5 | H31: =F31*G31 -> 0 | M31: =OR(AND(N31>=N30,O31>=O30,P31>=P30,Q31>=Q30),AND(N31>=N29,O31>=O29,P31>=P29,Q31>=Q29)) -> FALSE | N31: =IF(B31=$K$4,1,IF(B31=$L$4,3,2)) -> 1 | O31: =IF(C31=$K$5,1,IF(C31=$L$5,3,2)) -> 3 | P31: =IF(D31=$K$6,1,IF(D31=$L$6,3,2)) -> 2 | Q31: =IF(E31=$K$7,1,IF(E31=$L$7,3,2)) -> 2
A33: Question
A34: =A28+1 -> 5 | B34: =DOE!$B$2 -> price ($) | C34: =DOE!$C$2 -> Fluid Capacity (liters) | D34: =DOE!$D$2 -> Time to boil (sec) | E34: =DOE!$E$2 -> Boils per charge (#) | F34: Choice (mark with "1") | G34: Alt ID | M34: dominated? | N34: =B34 -> price ($) | O34: =C34 -> Fluid Capacity (liters) | P34: =D34 -> Time to boil (sec) | Q34: =E34 -> Boils per charge (#)
A35: Option 1 | B35: =INDEX(DOE!$A$4:$E$84,$G35,COLUMN(B:B)) -> 100 | C35: =INDEX(DOE!$A$4:$E$84,$G35,COLUMN(C:C)) -> 1 | D35: =INDEX(DOE!$A$4:$E$84,$G35,COLUMN(D:D)) -> 120 | E35: =INDEX(DOE!$A$4:$E$84,$G35,COLUMN(E:E)) -> 10 | F35: 1 | G35: =INDEX(StaticRandomNumbers!$A$4:$BJ$93,A34*3-2,$B$1+1) -> 39 | H35: =F35*G35 -> 39 | J35: =IF(AND(COUNTIF(F35:F37,"")=2,COUNTIF(F35:F37,1)=1),1,0) -> 1 | M35: =OR(AND(N35>=N36,O35>=O36,P35>=P36,Q35>=Q36),AND(N35>=N37,O35>=O37,P35>=P37,Q35>=Q37)) -> FALSE | N35: =IF(B35=$K$4,1,IF(B35=$L$4,3,2)) -> 2 | O35: =IF(C35=$K$5,1,IF(C35=$L$5,3,2)) -> 2 | P35: =IF(D35=$K$6,1,IF(D35=$L$6,3,2)) -> 1 | Q35: =IF(E35=$K$7,1,IF(E35=$L$7,3,2)) -> 1
A36: Option 2 | B36: =INDEX(DOE!$A$4:$E$84,$G36,COLUMN(B:B)) -> 50 | C36: =INDEX(DOE!$A$4:$E$84,$G36,COLUMN(C:C)) -> 2 | D36: =INDEX(DOE!$A$4:$E$84,$G36,COLUMN(D:D)) -> 120 | E36: =INDEX(DOE!$A$4:$E$84,$G36,COLUMN(E:E)) -> 5 | G36: =INDEX(StaticRandomNumbers!$A$4:$BJ$93,A34*3-1,$B$1+1) -> 20 | H36: =F36*G36 -> 0 | M36: =OR(AND(N35<=N36,O35<=O36,P35<=P36,Q35<=Q36),AND(N36>=N37,O36>=O37,P36>=P37,Q36>=Q37)) -> FALSE | N36: =IF(B36=$K$4,1,IF(B36=$L$4,3,2)) -> 1 | O36: =IF(C36=$K$5,1,IF(C36=$L$5,3,2)) -> 1 | P36: =IF(D36=$K$6,1,IF(D36=$L$6,3,2)) -> 1 | Q36: =IF(E36=$K$7,1,IF(E36=$L$7,3,2)) -> 2
A37: Option 3 | B37: =INDEX(DOE!$A$4:$E$84,$G37,COLUMN(B:B)) -> 50 | C37: =INDEX(DOE!$A$4:$E$84,$G37,COLUMN(C:C)) -> 0.25 | D37: =INDEX(DOE!$A$4:$E$84,$G37,COLUMN(D:D)) -> 600 | E37: =INDEX(DOE!$A$4:$E$84,$G37,COLUMN(E:E)) -> 5 | G37: =INDEX(StaticRandomNumbers!$A$4:$BJ$93,A34*3,$B$1+1) -> 8 | H37: =F37*G37 -> 0 | M37: =OR(AND(N37>=N36,O37>=O36,P37>=P36,Q37>=Q36),AND(N37>=N35,O37>=O35,P37>=P35,Q37>=Q35)) -> TRUE | N37: =IF(B37=$K$4,1,IF(B37=$L$4,3,2)) -> 1 | O37: =IF(C37=$K$5,1,IF(C37=$L$5,3,2)) -> 3 | P37: =IF(D37=$K$6,1,IF(D37=$L$6,3,2)) -> 3 | Q37: =IF(E37=$K$7,1,IF(E37=$L$7,3,2)) -> 2
A39: Question
A40: =A34+1 -> 6 | B40: =DOE!$B$2 -> price ($) | C40: =DOE!$C$2 -> Fluid Capacity (liters) | D40: =DOE!$D$2 -> Time to boil (sec) | E40: =DOE!$E$2 -> Boils per charge (#) | F40: Choice (mark with "1") | G40: Alt ID | M40: dominated? | N40: =B40 -> price ($) | O40: =C40 -> Fluid Capacity (liters) | P40: =D40 -> Time to boil (sec) | Q40: =E40 -> Boils per charge (#)
A41: Option 1 | B41: =INDEX(DOE!$A$4:$E$84,$G41,COLUMN(B:B)) -> 100 | C41: =INDEX(DOE!$A$4:$E$84,$G41,COLUMN(C:C)) -> 2 | D41: =INDEX(DOE!$A$4:$E$84,$G41,COLUMN(D:D)) -> 240 | E41: =INDEX(DOE!$A$4:$E$84,$G41,COLUMN(E:E)) -> 5 | F41: 1 | G41: =INDEX(StaticRandomNumbers!$A$4:$BJ$93,A40*3-2,$B$1+1) -> 50 | H41: =F41*G41 -> 50 | J41: =IF(AND(COUNTIF(F41:F43,"")=2,COUNTIF(F41:F43,1)=1),1,0) -> 1 | M41: =OR(AND(N41>=N42,O41>=O42,P41>=P42,Q41>=Q42),AND(N41>=N43,O41>=O43,P41>=P43,Q41>=Q43)) -> FALSE | N41: =IF(B41=$K$4,1,IF(B41=$L$4,3,2)) -> 2 | O41: =IF(C41=$K$5,1,IF(C41=$L$5,3,2)) -> 1 | P41: =IF(D41=$K$6,1,IF(D41=$L$6,3,2)) -> 2 | Q41: =IF(E41=$K$7,1,IF(E41=$L$7,3,2)) -> 2
A42: Option 2 | B42: =INDEX(DOE!$A$4:$E$84,$G42,COLUMN(B:B)) -> 50 | C42: =INDEX(DOE!$A$4:$E$84,$G42,COLUMN(C:C)) -> 1 | D42: =INDEX(DOE!$A$4:$E$84,$G42,COLUMN(D:D)) -> 240 | E42: =INDEX(DOE!$A$4:$E$84,$G42,COLUMN(E:E)) -> 10 | G42: =INDEX(StaticRandomNumbers!$A$4:$BJ$93,A40*3-1,$B$1+1) -> 15 | H42: =F42*G42 -> 0 | M42: =OR(AND(N41<=N42,O41<=O42,P41<=P42,Q41<=Q42),AND(N42>=N43,O42>=O43,P42>=P43,Q42>=Q43)) -> FALSE | N42: =IF(B42=$K$4,1,IF(B42=$L$4,3,2)) -> 1 | O42: =IF(C42=$K$5,1,IF(C42=$L$5,3,2)) -> 2 | P42: =IF(D42=$K$6,1,IF(D42=$L$6,3,2)) -> 2 | Q42: =IF(E42=$K$7,1,IF(E42=$L$7,3,2)) -> 1
A43: Option 3 | B43: =INDEX(DOE!$A$4:$E$84,$G43,COLUMN(B:B)) -> 100 | C43: =INDEX(DOE!$A$4:$E$84,$G43,COLUMN(C:C)) -> 2 | D43: =INDEX(DOE!$A$4:$E$84,$G43,COLUMN(D:D)) -> 600 | E43: =INDEX(DOE!$A$4:$E$84,$G43,COLUMN(E:E)) -> 10 | G43: =INDEX(StaticRandomNumbers!$A$4:$BJ$93,A40*3,$B$1+1) -> 54 | H43: =F43*G43 -> 0 | M43: =OR(AND(N43>=N42,O43>=O42,P43>=P42,Q43>=Q42),AND(N43>=N41,O43>=O41,P43>=P41,Q43>=Q41)) -> FALSE | N43: =IF(B43=$K$4,1,IF(B43=$L$4,3,2)) -> 2 | O43: =IF(C43=$K$5,1,IF(C43=$L$5,3,2)) -> 1 | P43: =IF(D43=$K$6,1,IF(D43=$L$6,3,2)) -> 3 | Q43: =IF(E43=$K$7,1,IF(E43=$L$7,3,2)) -> 1
A45: Question
A46: =A40+1 -> 7 | B46: =DOE!$B$2 -> price ($) | C46: =DOE!$C$2 -> Fluid Capacity (liters) | D46: =DOE!$D$2 -> Time to boil (sec) | E46: =DOE!$E$2 -> Boils per charge (#) | F46: Choice (mark with "1") | G46: Alt ID | M46: dominated? | N46: =B46 -> price ($) | O46: =C46 -> Fluid Capacity (liters) | P46: =D46 -> Time to boil (sec) | Q46: =E46 -> Boils per charge (#)
A47: Option 1 | B47: =INDEX(DOE!$A$4:$E$84,$G47,COLUMN(B:B)) -> 100 | C47: =INDEX(DOE!$A$4:$E$84,$G47,COLUMN(C:C)) -> 0.25 | D47: =INDEX(DOE!$A$4:$E$84,$G47,COLUMN(D:D)) -> 600 | E47: =INDEX(DOE!$A$4:$E$84,$G47,COLUMN(E:E)) -> 1 | G47: =INDEX(StaticRandomNumbers!$A$4:$BJ$93,A46*3-2,$B$1+1) -> 34 | H47: =F47*G47 -> 0 | J47: =IF(AND(COUNTIF(F47:F49,"")=2,COUNTIF(F47:F49,1)=1),1,0) -> 1 | M47: =OR(AND(N47>=N48,O47>=O48,P47>=P48,Q47>=Q48),AND(N47>=N49,O47>=O49,P47>=P49,Q47>=Q49)) -> TRUE | N47: =IF(B47=$K$4,1,IF(B47=$L$4,3,2)) -> 2 | O47: =IF(C47=$K$5,1,IF(C47=$L$5,3,2)) -> 3 | P47: =IF(D47=$K$6,1,IF(D47=$L$6,3,2)) -> 3 | Q47: =IF(E47=$K$7,1,IF(E47=$L$7,3,2)) -> 3
A48: Option 2 | B48: =INDEX(DOE!$A$4:$E$84,$G48,COLUMN(B:B)) -> 100 | C48: =INDEX(DOE!$A$4:$E$84,$G48,COLUMN(C:C)) -> 0.25 | D48: =INDEX(DOE!$A$4:$E$84,$G48,COLUMN(D:D)) -> 120 | E48: =INDEX(DOE!$A$4:$E$84,$G48,COLUMN(E:E)) -> 1 | G48: =INDEX(StaticRandomNumbers!$A$4:$BJ$93,A46*3-1,$B$1+1) -> 28 | H48: =F48*G48 -> 0 | M48: =OR(AND(N47<=N48,O47<=O48,P47<=P48,Q47<=Q48),AND(N48>=N49,O48>=O49,P48>=P49,Q48>=Q49)) -> FALSE | N48: =IF(B48=$K$4,1,IF(B48=$L$4,3,2)) -> 2 | O48: =IF(C48=$K$5,1,IF(C48=$L$5,3,2)) -> 3 | P48: =IF(D48=$K$6,1,IF(D48=$L$6,3,2)) -> 1 | Q48: =IF(E48=$K$7,1,IF(E48=$L$7,3,2)) -> 3
...

Sheet SurveyResultAggregation
A1: This Survey | B1: Result Aggregation
A2: ="ID = "&Survey!B1 -> ID = 9 | B2: Alt ID | C2: TOTAL | D2: Survey 1 | E2: Survey 2 | F2: Survey 3 | G2: Survey 4 | H2: Survey 5 | I2: Survey 6 | J2: Survey 7 | K2: Survey 8 | L2: Survey 9 | M2: Survey 10 | N2: Survey 11 | O2: Survey 12 | P2: Survey 13 | Q2: Survey 14 | R2: Survey 15 | S2: Survey 16 | T2: Survey 17 | U2: Survey 18 | V2: Survey 19 | W2: Survey 20 | X2: Survey 21 | Y2: Survey 22 | Z2: Survey 23 | AA2: Survey 24 | AB2: Survey 25 | AC2: Survey 26 | AD2: Survey 27 | AE2: Survey 28 | AF2: Survey 29 | AG2: Survey 30 | AH2: Survey 31 | AI2: Survey 32 | AJ2: Survey 33 | AK2: Survey 34 | AL2: Survey 35 | AM2: Survey 36 | AN2: Survey 37 | AO2: Survey 38 | AP2: Survey 39 | AQ2: Survey 40 | AR2: Survey 41 | AS2: Survey 42 | AT2: Survey 43 | AU2: Survey 44 | AV2: Survey 45 | AW2: Survey 46 | AX2: Survey 47 | AY2: Survey 48 | AZ2: Survey 49 | BA2: Survey 50 | BB2: Survey 51 | BC2: Survey 52 | BD2: Survey 53 | BE2: Survey 54 | BF2: Survey 55 | BG2: Survey 56 | BH2: Survey 57 | BI2: Survey 58 | BJ2: Survey 59 | BK2: Survey 60
A3: =COUNTIF(Survey!H:H,DOE!$A4) -> 0 | B3: 1 | C3: =SUM(SurveyResultAggregation!$D3:$BK3) -> 1 | K3: 0 | L3: 0 | O3: 0 | Q3: 0 | AC3: 0 | AW3: 1
A4: =COUNTIF(Survey!H:H,DOE!$A5) -> 0 | B4: 2 | C4: =SUM(SurveyResultAggregation!$D4:$BK4) -> 1 | K4: 0 | L4: 0 | O4: 0 | Q4: 0 | AC4: 0 | AW4: 1
A5: =COUNTIF(Survey!H:H,DOE!$A6) -> 0 | B5: 3 | C5: =SUM(SurveyResultAggregation!$D5:$BK5) -> 0 | K5: 0 | L5: 0 | O5: 0 | Q5: 0 | AC5: 0 | AW5: 0
A6: =COUNTIF(Survey!H:H,DOE!$A7) -> 0 | B6: 4 | C6: =SUM(SurveyResultAggregation!$D6:$BK6) -> 2 | K6: 0 | L6: 0 | O6: 0 | Q6: 1 | AC6: 0 | AW6: 1
A7: =COUNTIF(Survey!H:H,DOE!$A8) -> 0 | B7: 5 | C7: =SUM(SurveyResultAggregation!$D7:$BK7) -> 1 | K7: 0 | L7: 0 | O7: 0 | Q7: 0 | AC7: 0 | AW7: 1
A8: =COUNTIF(Survey!H:H,DOE!$A9) -> 0 | B8: 6 | C8: =SUM(SurveyResultAggregation!$D8:$BK8) -> 2 | K8: 0 | L8: 0 | O8: 0 | Q8: 1 | AC8: 0 | AW8: 1
A9: =COUNTIF(Survey!H:H,DOE!$A10) -> 0 | B9: 7 | C9: =SUM(SurveyResultAggregation!$D9:$BK9) -> 0 | K9: 0 | L9: 0 | O9: 0 | Q9: 0 | AC9: 0 | AW9: 0
A10: =COUNTIF(Survey!H:H,DOE!$A11) -> 0 | B10: 8 | C10: =SUM(SurveyResultAggregation!$D10:$BK10) -> 0 | K10: 0 | L10: 0 | O10: 0 | Q10: 0 | AC10: 0 | AW10: 0
A11: =COUNTIF(Survey!H:H,DOE!$A12) -> 0 | B11: 9 | C11: =SUM(SurveyResultAggregation!$D11:$BK11) -> 0 | K11: 0 | L11: 0 | O11: 0 | Q11: 0 | AC11: 0 | AW11: 0
A12: =COUNTIF(Survey!H:H,DOE!$A13) -> 2 | B12: 10 | C12: =SUM(SurveyResultAggregation!$D12:$BK12) -> 4 | K12: 0 | L12: 2 | O12: 0 | Q12: 1 | AC12: 0 | AW12: 1
A13: =COUNTIF(Survey!H:H,DOE!$A14) -> 2 | B13: 11 | C13: =SUM(SurveyResultAggregation!$D13:$BK13) -> 5 | K13: 1 | L13: 2 | O13: 1 | Q13: 0 | AC13: 1 | AW13: 0
A14: =COUNTIF(Survey!H:H,DOE!$A15) -> 0 | B14: 12 | C14: =SUM(SurveyResultAggregation!$D14:$BK14) -> 2 | K14: 0 | L14: 0 | O14: 0 | Q14: 0 | AC14: 2 | AW14: 0
... A83: =COUNTIF(Survey!H:H,DOE!$A84) -> 0 | B83: 81 | C83: =SUM(SurveyResultAggregation!$D83:$BK83) -> 0 | K83: 0 | L83: 0 | O83: 0 | Q83: 0 | AC83: 0 | AW83: 0

Sheet SurveySetup
A1: Setup Your Survey
A2: Attribute Name | B2: Units | C2: Low | D2: Medium | E2: High
A3: price | B3: $ | C3: 50 | D3: 100 | E3: 200
A4: Fluid Capacity | B4: liters | C4: 0.25 | D4: 1 | E4: 2
A5: Time to boil | B5: sec | C5: 120 | D5: 240 | E5: 600
A6: Boils per charge | B6: # | C6: 1 | D6: 5 | E6: 10

Sheet ResultsInterpretation
A1: Demand Model Results
A2: Attribute Name | B2: Units | C2: bi | D2: si | E2: si [%]
A3: =SurveySetup!A3 -> price | B3: =SurveySetup!B3 -> $ | C3: =MaxLikelihoodSolver!K12 -> -0.0090891018 | D3: =MaxLikelihoodSolver!M12 -> 0.0018304608 | E3: =D3/ABS(C3) -> 0.20139072
A4: =SurveySetup!A4 -> Fluid Capacity | B4: =SurveySetup!B4 -> liters | C4: =MaxLikelihoodSolver!K13 -> 0.71797282 | D4: =MaxLikelihoodSolver!M13 -> 0.13463082 | E4: =D4/ABS(C4) -> 0.18751521
A5: =SurveySetup!A5 -> Time to boil | B5: =SurveySetup!B5 -> sec | C5: =MaxLikelihoodSolver!K14 -> -0.001463119 | D5: =MaxLikelihoodSolver!M14 -> 0.00050345617 | E5: =D5/ABS(C5) -> 0.3440979
A6: =SurveySetup!A6 -> Boils per charge | B6: =SurveySetup!B6 -> # | C6: =MaxLikelihoodSolver!K15 -> 0.080732285 | D6: =MaxLikelihoodSolver!M15 -> 0.025109421 | E6: =D6/ABS(C6) -> 0.31102081
A9: Plots of Relative Utility (with 95% confidence bounds)
A34: Data for Relative Utility Plots
A35: Attribute | B35: min | C35: max | D35: normalized rel util @ min | E35: normalized rel util @ max | F35: 95% low unc bound @ min | G35: 95% low unc bound @ max | H35: 95% up unc bound @ min | I35: 95% up unc bound @ max
A36: p | B36: =MIN(SurveySetup!C3:E3) -> 50 | C36: =MAX(SurveySetup!C3:E3) -> 200 | D36: 0 | E36: =(C36-B36)*C3 -> -1.3633653 | F36: 0 | G36: =(C36-B36)*(C3-2*D3) -> -1.9125035 | H36: 0 | I36: =(C36-B36)*(C3+2*D3) -> -0.81422703
A37: x1 | B37: =MIN(SurveySetup!C4:E4) -> 0.25 | C37: =MAX(SurveySetup!C4:E4) -> 2 | D37: 0 | E37: =(C37-B37)*C4 -> 1.2564524 | F37: 0 | G37: =(C37-B37)*(C4-2*D4) -> 0.78524455 | H37: 0 | I37: =(C37-B37)*(C4+2*D4) -> 1.7276603
A38: x2 | B38: =MIN(SurveySetup!C5:E5) -> 120 | C38: =MAX(SurveySetup!C5:E5) -> 600 | D38: 0 | E38: =(C38-B38)*C5 -> -0.70229711 | F38: 0 | G38: =(C38-B38)*(C5-2*D5) -> -1.185615 | H38: 0 | I38: =(C38-B38)*(C5+2*D5) -> -0.21897919
A39: x3 | B39: =MIN(SurveySetup!C6:E6) -> 1 | C39: =MAX(SurveySetup!C6:E6) -> 10 | D39: 0 | E39: =(C39-B39)*C6 -> 0.72659057 | F39: 0 | G39: =(C39-B39)*(C6-2*D6) -> 0.27462099 | H39: 0 | I39: =(C39-B39)*(C6+2*D6) -> 1.1785601
A40: Overall min | B40: =MIN(ResultsInterpretation!$G$36:$G$39,ResultsInterpretation!$I$36:$I$39) -> -1.9125035
A41: Overall max | B41: =MAX(ResultsInterpretation!$G$36:$G$39,ResultsInterpretation!$I$36:$I$39) -> 1.7276603

Sheet DemandPredictionModel
A1: The Best-Fit Multinomial Logit Model with Utility Linear in the Attributes
A3: Demand Model Results
A4: Attribute Name | B4: Units | C4: bi | D4: si | E4: si [%]
A5: =SurveySetup!A3 -> price | B5: =SurveySetup!B3 -> $ | C5: =MaxLikelihoodSolver!K12 -> -0.0090891018 | D5: =MaxLikelihoodSolver!M12 -> 0.0018304608 | E5: =D5/ABS(C5) -> 0.20139072
A6: =SurveySetup!A4 -> Fluid Capacity | B6: =SurveySetup!B4 -> liters | C6: =MaxLikelihoodSolver!K13 -> 0.71797282 | D6: =MaxLikelihoodSolver!M13 -> 0.13463082 | E6: =D6/ABS(C6) -> 0.18751521
A7: =SurveySetup!A5 -> Time to boil | B7: =SurveySetup!B5 -> sec | C7: =MaxLikelihoodSolver!K14 -> -0.001463119 | D7: =MaxLikelihoodSolver!M14 -> 0.00050345617 | E7: =D7/ABS(C7) -> 0.3440979
A8: =SurveySetup!A6 -> Boils per charge | B8: =SurveySetup!B6 -> # | C8: =MaxLikelihoodSolver!K15 -> 0.080732285 | D8: =MaxLikelihoodSolver!M15 -> 0.025109421 | E8: =D8/ABS(C8) -> 0.31102081
A10: Specify the Market Situation
A11: Attribute Name | B11: Units | C11: Competitor 1 | D11: Competitor 2 | E11: Competitor 3 | F11: Competitor 4
A12: =SurveySetup!A3 -> price | B12: =SurveySetup!B3 -> $ | C12: 95 | D12: 50 | E12: 135 | F12: 200
A13: =SurveySetup!A4 -> Fluid Capacity | B13: =SurveySetup!B4 -> liters | C13: 1 | D13: 0.25 | E13: 2 | F13: 1
A14: =SurveySetup!A5 -> Time to boil | B14: =SurveySetup!B5 -> sec | C14: 600 | D14: 600 | E14: 200 | F14: 125
A15: =SurveySetup!A6 -> Boils per charge | B15: =SurveySetup!B6 -> # | C15: 1 | D15: 2 | E15: 1 | F15: 10
A17: Total Market Size | B17: customers | C17: 20000
A19: Provide Inputs for the Demand Prediction
A20: Attribute Name | B20: Units | C20: Input from ModelCenter
A21: fixedCost | B21: =SurveySetup!B3 -> $ | C21: 150
A22: marginalCost | B22: =SurveySetup!B3 -> $ | C22: 27
A23: capacity | B23: items | C23: 20000
A24: =SurveySetup!A4 -> Fluid Capacity | B24: =SurveySetup!B4 -> liters | C24: 0.2355
A25: =SurveySetup!A5 -> Time to boil | B25: =SurveySetup!B5 -> sec | C25: 42.669274
A26: =SurveySetup!A6 -> Boils per charge | B26: =SurveySetup!B6 -> # | C26: 9.3588135
A28: Demand Prediction Outputs
A29: Attribute Name | B29: Units | C29: Output to ModelCenter
A30: demand | B30: items | C30: =IF(PredictionSolver!$A$133<=capacity,PredictionSolver!$A$133,capacity) -> 3714.3327
A31: price | B31: =SurveySetup!B3 -> $ | C31: =IF(PredictionSolver!$A$133<=capacity,PredictionSolver!$A$132,PredictionSolver!$A$137) -> 162.11497
A32: revenue | B32: =SurveySetup!B3 -> $ | C32: =price*demand -> 602148.94
A33: profit | B33: =SurveySetup!B3 -> $ | C33: =demand*(price-marginalCost)-fixedCost -> 501711.95

Sheet Utility
A1: Risk Tolerance | B1: =SurveySetup!B3 -> $ | C1: 1e+100
A3: utility | B3: utils | C3: =IF(riskTolerance>profit*100000, profit - profit*profit/riskTolerance/2 + profit*profit*profit/riskTolerance/riskTolerance/6, riskTolerance*(1-EXP(-profit/riskTolerance))) -> 501711.95

Sheet DOE
A1: Full Factorial Design
B2: =CONCATENATE(SurveySetup!A3, " (", SurveySetup!B3, ")") -> price ($) | C2: =CONCATENATE(SurveySetup!A4, " (", SurveySetup!B4, ")") -> Fluid Capacity (liters) | D2: =CONCATENATE(SurveySetup!A5, " (", SurveySetup!B5, ")") -> Time to boil (sec) | E2: =CONCATENATE(SurveySetup!A6, " (", SurveySetup!B6, ")") -> Boils per charge (#)
A3: Alt ID | B3: a1 | C3: a2 | D3: a3 | E3: a4
A4: 1 | B4: =SurveySetup!$C$3 -> 50 | C4: =SurveySetup!$C$4 -> 0.25 | D4: =SurveySetup!$C$5 -> 120 | E4: =SurveySetup!$C$6 -> 1
A5: 2 | B5: =SurveySetup!$C$3 -> 50 | C5: =SurveySetup!$C$4 -> 0.25 | D5: =SurveySetup!$C$5 -> 120 | E5: =SurveySetup!$D$6 -> 5
A6: 3 | B6: =SurveySetup!$C$3 -> 50 | C6: =SurveySetup!$C$4 -> 0.25 | D6: =SurveySetup!$C$5 -> 120 | E6: =SurveySetup!$E$6 -> 10
A7: 4 | B7: =SurveySetup!$C$3 -> 50 | C7: =SurveySetup!$C$4 -> 0.25 | D7: =SurveySetup!$D$5 -> 240 | E7: =SurveySetup!$C$6 -> 1
A8: 5 | B8: =SurveySetup!$C$3 -> 50 | C8: =SurveySetup!$C$4 -> 0.25 | D8: =SurveySetup!$D$5 -> 240 | E8: =SurveySetup!$D$6 -> 5
A9: 6 | B9: =SurveySetup!$C$3 -> 50 | C9: =SurveySetup!$C$4 -> 0.25 | D9: =SurveySetup!$D$5 -> 240 | E9: =SurveySetup!$E$6 -> 10
A10: 7 | B10: =SurveySetup!$C$3 -> 50 | C10: =SurveySetup!$C$4 -> 0.25 | D10: =SurveySetup!$E$5 -> 600 | E10: =SurveySetup!$C$6 -> 1
A11: 8 | B11: =SurveySetup!$C$3 -> 50 | C11: =SurveySetup!$C$4 -> 0.25 | D11: =SurveySetup!$E$5 -> 600 | E11: =SurveySetup!$D$6 -> 5
A12: 9 | B12: =SurveySetup!$C$3 -> 50 | C12: =SurveySetup!$C$4 -> 0.25 | D12: =SurveySetup!$E$5 -> 600 | E12: =SurveySetup!$E$6 -> 10
A13: 10 | B13: =SurveySetup!$C$3 -> 50 | C13: =SurveySetup!$D$4 -> 1 | D13: =SurveySetup!$C$5 -> 120 | E13: =SurveySetup!$C$6 -> 1
A14: 11 | B14: =SurveySetup!$C$3 -> 50 | C14: =SurveySetup!$D$4 -> 1 | D14: =SurveySetup!$C$5 -> 120 | E14: =SurveySetup!$D$6 -> 5
A15: 12 | B15: =SurveySetup!$C$3 -> 50 | C15: =SurveySetup!$D$4 -> 1 | D15: =SurveySetup!$C$5 -> 120 | E15: =SurveySetup!$E$6 -> 10
A16: 13 | B16: =SurveySetup!$C$3 -> 50 | C16: =SurveySetup!$D$4 -> 1 | D16: =SurveySetup!$D$5 -> 240 | E16: =SurveySetup!$C$6 -> 1
A17: 14 | B17: =SurveySetup!$C$3 -> 50 | C17: =SurveySetup!$D$4 -> 1 | D17: =SurveySetup!$D$5 -> 240 | E17: =SurveySetup!$D$6 -> 5
A18: 15 | B18: =SurveySetup!$C$3 -> 50 | C18: =SurveySetup!$D$4 -> 1 | D18: =SurveySetup!$D$5 -> 240 | E18: =SurveySetup!$E$6 -> 10
A19: 16 | B19: =SurveySetup!$C$3 -> 50 | C19: =SurveySetup!$D$4 -> 1 | D19: =SurveySetup!$E$5 -> 600 | E19: =SurveySetup!$C$6 -> 1
A20: 17 | B20: =SurveySetup!$C$3 -> 50 | C20: =SurveySetup!$D$4 -> 1 | D20: =SurveySetup!$E$5 -> 600 | E20: =SurveySetup!$D$6 -> 5
A21: 18 | B21: =SurveySetup!$C$3 -> 50 | C21: =SurveySetup!$D$4 -> 1 | D21: =SurveySetup!$E$5 -> 600 | E21: =SurveySetup!$E$6 -> 10
A22: 19 | B22: =SurveySetup!$C$3 -> 50 | C22: =SurveySetup!$E$4 -> 2 | D22: =SurveySetup!$C$5 -> 120 | E22: =SurveySetup!$C$6 -> 1
A23: 20 | B23: =SurveySetup!$C$3 -> 50 | C23: =SurveySetup!$E$4 -> 2 | D23: =SurveySetup!$C$5 -> 120 | E23: =SurveySetup!$D$6 -> 5
A24: 21 | B24: =SurveySetup!$C$3 -> 50 | C24: =SurveySetup!$E$4 -> 2 | D24: =SurveySetup!$C$5 -> 120 | E24: =SurveySetup!$E$6 -> 10
A25: 22 | B25: =SurveySetup!$C$3 -> 50 | C25: =SurveySetup!$E$4 -> 2 | D25: =SurveySetup!$D$5 -> 240 | E25: =SurveySetup!$C$6 -> 1
A26: 23 | B26: =SurveySetup!$C$3 -> 50 | C26: =SurveySetup!$E$4 -> 2 | D26: =SurveySetup!$D$5 -> 240 | E26: =SurveySetup!$D$6 -> 5
A27: 24 | B27: =SurveySetup!$C$3 -> 50 | C27: =SurveySetup!$E$4 -> 2 | D27: =SurveySetup!$D$5 -> 240 | E27: =SurveySetup!$E$6 -> 10
A28: 25 | B28: =SurveySetup!$C$3 -> 50 | C28: =SurveySetup!$E$4 -> 2 | D28: =SurveySetup!$E$5 -> 600 | E28: =SurveySetup!$C$6 -> 1
A29: 26 | B29: =SurveySetup!$C$3 -> 50 | C29: =SurveySetup!$E$4 -> 2 | D29: =SurveySetup!$E$5 -> 600 | E29: =SurveySetup!$D$6 -> 5
A30: 27 | B30: =SurveySetup!$C$3 -> 50 | C30: =SurveySetup!$E$4 -> 2 | D30: =SurveySetup!$E$5 -> 600 | E30: =SurveySetup!$E$6 -> 10
A31: 28 | B31: =SurveySetup!$D$3 -> 100 | C31: =SurveySetup!$C$4 -> 0.25 | D31: =SurveySetup!$C$5 -> 120 | E31: =SurveySetup!$C$6 -> 1
A32: 29 | B32: =SurveySetup!$D$3 -> 100 | C32: =SurveySetup!$C$4 -> 0.25 | D32: =SurveySetup!$C$5 -> 120 | E32: =SurveySetup!$D$6 -> 5
A33: 30 | B33: =SurveySetup!$D$3 -> 100 | C33: =SurveySetup!$C$4 -> 0.25 | D33: =SurveySetup!$C$5 -> 120 | E33: =SurveySetup!$E$6 -> 10
A34: 31 | B34: =SurveySetup!$D$3 -> 100 | C34: =SurveySetup!$C$4 -> 0.25 | D34: =SurveySetup!$D$5 -> 240 | E34: =SurveySetup!$C$6 -> 1
A35: 32 | B35: =SurveySetup!$D$3 -> 100 | C35: =SurveySetup!$C$4 -> 0.25 | D35: =SurveySetup!$D$5 -> 240 | E35: =SurveySetup!$D$6 -> 5
A36: 33 | B36: =SurveySetup!$D$3 -> 100 | C36: =SurveySetup!$C$4 -> 0.25 | D36: =SurveySetup!$D$5 -> 240 | E36: =SurveySetup!$E$6 -> 10
A37: 34 | B37: =SurveySetup!$D$3 -> 100 | C37: =SurveySetup!$C$4 -> 0.25 | D37: =SurveySetup!$E$5 -> 600 | E37: =SurveySetup!$C$6 -> 1
A38: 35 | B38: =SurveySetup!$D$3 -> 100 | C38: =SurveySetup!$C$4 -> 0.25 | D38: =SurveySetup!$E$5 -> 600 | E38: =SurveySetup!$D$6 -> 5
A39: 36 | B39: =SurveySetup!$D$3 -> 100 | C39: =SurveySetup!$C$4 -> 0.25 | D39: =SurveySetup!$E$5 -> 600 | E39: =SurveySetup!$E$6 -> 10
A40: 37 | B40: =SurveySetup!$D$3 -> 100 | C40: =SurveySetup!$D$4 -> 1 | D40: =SurveySetup!$C$5 -> 120 | E40: =SurveySetup!$C$6 -> 1
...

Sheet MaxLikelihoodSolver
A1: Normalized Inputs -- The survey results
A2: index | B2: 1 | C2: 2 | D2: 3 | E2: 4 | F2: 5 | G2: 6 | H2: 7 | I2: 8 | J2: 9 | K2: 10 | L2: 11 | M2: 12 | N2: 13 | O2: 14 | P2: 15 | Q2: 16 | R2: 17 | S2: 18 | T2: 19 | U2: 20 | V2: 21 | W2: 22 | X2: 23 | Y2: 24 | Z2: 25 | AA2: 26 | AB2: 27 | AC2: 28 | AD2: 29 | AE2: 30 | AF2: 31 | AG2: 32 | AH2: 33 | AI2: 34 | AJ2: 35 | AK2: 36 | AL2: 37 | AM2: 38 | AN2: 39 | AO2: 40 | AP2: 41 | AQ2: 42 | AR2: 43 | AS2: 44 | AT2: 45 | AU2: 46 | AV2: 47 | AW2: 48 | AX2: 49 | AY2: 50 | AZ2: 51 | BA2: 52 | BB2: 53 | BC2: 54 | BD2: 55 | BE2: 56 | BF2: 57 | BG2: 58 | BH2: 59 | BI2: 60 | BJ2: 61 | BK2: 62 | BL2: 63 | BM2: 64 | BN2: 65 | BO2: 66 | BP2: 67 | BQ2: 68 | BR2: 69 | BS2: 70 | BT2: 71 | BU2: 72 | BV2: 73 | BW2: 74 | BX2: 75 | BY2: 76 | BZ2: 77 | CA2: 78 | CB2: 79 | CC2: 80 | CD2: 81 | CE2: Totals | CH2: Max | CI2: Min | CJ2: Scaling | CK2: Offset
A3: pj | B3: =(DOE!A87-$CK3)/$CJ3 -> -1 | C3: =(DOE!B87-$CK3)/$CJ3 -> -1 | D3: =(DOE!C87-$CK3)/$CJ3 -> -1 | E3: =(DOE!D87-$CK3)/$CJ3 -> -1 | F3: =(DOE!E87-$CK3)/$CJ3 -> -1 | G3: =(DOE!F87-$CK3)/$CJ3 -> -1 | H3: =(DOE!G87-$CK3)/$CJ3 -> -1 | I3: =(DOE!H87-$CK3)/$CJ3 -> -1 | ... CD3: =(DOE!CC87-$CK3)/$CJ3 -> 1 | CE3: =SUMPRODUCT(MaxLikelihoodSolver!$B3:$CD3,$B$7:$CD$7) -> -60.666667 | CF3: SumProduct with n_j | CH3: =MAX(SurveySetup!C3:E3) -> 200 | CI3: =MIN(SurveySetup!C3:E3) -> 50 | CJ3: =(CH3-CI3)/2 -> 75 | CK3: =CJ3+CI3 -> 125
A4: x1j | B4: =(DOE!A88-$CK4)/$CJ4 -> -1 | C4: =(DOE!B88-$CK4)/$CJ4 -> -1 | D4: =(DOE!C88-$CK4)/$CJ4 -> -1 | E4: =(DOE!D88-$CK4)/$CJ4 -> -1 | F4: =(DOE!E88-$CK4)/$CJ4 -> -1 | G4: =(DOE!F88-$CK4)/$CJ4 -> -1 | H4: =(DOE!G88-$CK4)/$CJ4 -> -1 | I4: =(DOE!H88-$CK4)/$CJ4 -> -1 | ... CD4: =(DOE!CC88-$CK4)/$CJ4 -> 1 | CE4: =SUMPRODUCT(MaxLikelihoodSolver!$B4:$CD4,$B$7:$CD$7) -> 43.714286 | CF4: SumProduct with n_j | CH4: =MAX(SurveySetup!C4:E4) -> 2 | CI4: =MIN(SurveySetup!C4:E4) -> 0.25 | CJ4: =(CH4-CI4)/2 -> 0.875 | CK4: =CJ4+CI4 -> 1.125
A5: x2j | B5: =(DOE!A89-$CK5)/$CJ5 -> -1 | C5: =(DOE!B89-$CK5)/$CJ5 -> -1 | D5: =(DOE!C89-$CK5)/$CJ5 -> -1 | E5: =(DOE!D89-$CK5)/$CJ5 -> -0.5 | F5: =(DOE!E89-$CK5)/$CJ5 -> -0.5 | G5: =(DOE!F89-$CK5)/$CJ5 -> -0.5 | H5: =(DOE!G89-$CK5)/$CJ5 -> 1 | I5: =(DOE!H89-$CK5)/$CJ5 -> 1 | ... CD5: =(DOE!CC89-$CK5)/$CJ5 -> 1 | CE5: =SUMPRODUCT(MaxLikelihoodSolver!$B5:$CD5,$B$7:$CD$7) -> -47.5 | CF5: SumProduct with n_j | CH5: =MAX(SurveySetup!C5:E5) -> 600 | CI5: =MIN(SurveySetup!C5:E5) -> 120 | CJ5: =(CH5-CI5)/2 -> 240 | CK5: =CJ5+CI5 -> 360
A6: x3j | B6: =(DOE!A90-$CK6)/$CJ6 -> -1 | C6: =(DOE!B90-$CK6)/$CJ6 -> -0.11111111 | D6: =(DOE!C90-$CK6)/$CJ6 -> 1 | E6: =(DOE!D90-$CK6)/$CJ6 -> -1 | F6: =(DOE!E90-$CK6)/$CJ6 -> -0.11111111 | G6: =(DOE!F90-$CK6)/$CJ6 -> 1 | H6: =(DOE!G90-$CK6)/$CJ6 -> -1 | I6: =(DOE!H90-$CK6)/$CJ6 -> -0.11111111 | ... CD6: =(DOE!CC90-$CK6)/$CJ6 -> 1 | CE6: =SUMPRODUCT(MaxLikelihoodSolver!$B6:$CD6,$B$7:$CD$7) -> 24.666667 | CF6: SumProduct with n_j | CH6: =MAX(SurveySetup!C6:E6) -> 10 | CI6: =MIN(SurveySetup!C6:E6) -> 1 | CJ6: =(CH6-CI6)/2 -> 4.5 | CK6: =CJ6+CI6 -> 5.5
A7: nj | B7: {=TRANSPOSE(SurveyResultAggregation!$C$3:$C$83)} -> 1 | C7: 1 | D7: 0 | E7: 2 | F7: 1 | G7: 2 | H7: 0 | I7: 0 | J7: 0 | K7: 4 | L7: 5 | M7: 2 | N7: 0 | O7: 5 | P7: 4 | Q7: 1 | R7: 3 | S7: 3 | T7: 4 | U7: 3 | V7: 6 | W7: 2 | X7: 4 | Y7: 4 | Z7: 0 | AA7: 4 | AB7: 2 | AC7: 0 | AD7: 0 | AE7: 0 | AF7: 0 | AG7: 0 | AH7: 2 | AI7: 0 | AJ7: 0 | AK7: 0 | AL7: 1 | AM7: 3 | AN7: 1 | AO7: 3 | AP7: 1 | AQ7: 3 | AR7: 0 | AS7: 1 | AT7: 2 | AU7: 0 | AV7: 3 | AW7: 6 | AX7: 2 | AY7: 5 | AZ7: 2 | BA7: 1 | BB7: 2 | BC7: 3 | BD7: 0 | BE7: 0 | BF7: 0 | BG7: 0 | BH7: 0 | BI7: 0 | BJ7: 0 | BK7: 0 | BL7: 0 | BM7: 0 | BN7: 1 | BO7: 3 | BP7: 0 | BQ7: 2 | BR7: 2 | BS7: 0 | BT7: 1 | BU7: 0 | BV7: 0 | BW7: 0 | BX7: 3 | BY7: 0 | BZ7: 2 | CA7: 1 | CB7: 0 | CC7: 1 | CD7: 0 | CE7: =SUM(MaxLikelihoodSolver!$B7:$CD7) -> 120 | CF7: Sum
A8: POBS | B8: =B7/$CE$7 -> 0.0083333333 | C8: =C7/$CE$7 -> 0.0083333333 | D8: =D7/$CE$7 -> 0 | E8: =E7/$CE$7 -> 0.016666667 | F8: =F7/$CE$7 -> 0.0083333333 | G8: =G7/$CE$7 -> 0.016666667 | H8: =H7/$CE$7 -> 0 | I8: =I7/$CE$7 -> 0 | ... CD8: =CD7/$CE$7 -> 0 | CE8: =SUM(MaxLikelihoodSolver!$B8:$CD8) -> 1 | CF8: Sum
A10: Optimization Iterations -- for debugging | K10: Optimization Results -- after rescaling | O10: Hessian -- scaled
A11: iteration | B11: beta0 | C11: beta1 | D11: beta2 | E11: beta3 | F11: lnL | G11: alpha | H11: NormGradient | K11: beta | L11: gradient | M11: sigma | O11: =B915 -> -53.057894 | P11: =C915 -> 0.45685547 | Q11: =D915 -> 0.45685547 | R11: =E915 -> 0.45685547
A12: 1 | B12: =INDEX(B:B,ROW($B$34)+(MaxLikelihoodSolver!$A12-1)*(94-36)) -> 0 | C12: =INDEX(B:B,ROW($B$35)+(MaxLikelihoodSolver!$A12-1)*(94-36)) -> 0 | D12: =INDEX(B:B,ROW($B$36)+(MaxLikelihoodSolver!$A12-1)*(94-36)) -> 0 | E12: =INDEX(B:B,ROW($B$37)+(MaxLikelihoodSolver!$A12-1)*(94-36)) -> 0 | F12: =INDEX(F:F,ROW($F$36)+(MaxLikelihoodSolver!$A12-1)*(94-36)) -> -527.3339 | G12: =INDEX(H:H,ROW($H$85)+(MaxLikelihoodSolver!$A12-1)*(94-36)) -> 0.65234375 | H12: =INDEX(F:F,ROW($F$34)+(MaxLikelihoodSolver!$A12-1)*(94-36)) -> 6287.3349 | K12: =K897/$CJ3 -> -0.0090891018 | L12: =L897*$CJ3 -> 4.2632564e-12 | M12: =SQRT(O17)/$CJ3 -> 0.0018304608 | O12: =B916 -> -0.32919413 | P12: =C916 -> -72.056326 | Q12: =D916 -> -0.32919413 | R12: =E916 -> -0.32919413
A13: 2 | B13: =INDEX(B:B,ROW($B$34)+(MaxLikelihoodSolver!$A13-1)*(94-36)) -> -0.62469141 | C13: =INDEX(B:B,ROW($B$35)+(MaxLikelihoodSolver!$A13-1)*(94-36)) -> 0.65234375 | D13: =INDEX(B:B,ROW($B$36)+(MaxLikelihoodSolver!$A13-1)*(94-36)) -> -0.36293691 | E13: =INDEX(B:B,ROW($B$37)+(MaxLikelihoodSolver!$A13-1)*(94-36)) -> 0.38419988 | F13: =INDEX(F:F,ROW($F$36)+(MaxLikelihoodSolver!$A13-1)*(94-36)) -> -487.36901 | G13: =INDEX(H:H,ROW($H$85)+(MaxLikelihoodSolver!$A13-1)*(94-36)) -> 0.053512573 | H13: =INDEX(F:F,ROW($F$34)+(MaxLikelihoodSolver!$A13-1)*(94-36)) -> 16.04702 | K13: =K898/$CJ4 -> 0.71797282 | L13: =L898*$CJ4 -> 0 | M13: =SQRT(P18)/$CJ4 -> 0.13463082 | O13: =B917 -> 0.35770278 | P13: =C917 -> 0.35770278 | Q13: =D917 -> -68.494824 | R13: =E917 -> 0.35770278
A14: 3 | B14: =INDEX(B:B,ROW($B$34)+(MaxLikelihoodSolver!$A14-1)*(94-36)) -> -0.67820399 | C14: =INDEX(B:B,ROW($B$35)+(MaxLikelihoodSolver!$A14-1)*(94-36)) -> 0.62734158 | D14: =INDEX(B:B,ROW($B$36)+(MaxLikelihoodSolver!$A14-1)*(94-36)) -> -0.35144284 | E14: =INDEX(B:B,ROW($B$37)+(MaxLikelihoodSolver!$A14-1)*(94-36)) -> 0.35947798 | F14: =INDEX(F:F,ROW($F$36)+(MaxLikelihoodSolver!$A14-1)*(94-36)) -> -487.23896 | G14: =INDEX(H:H,ROW($H$85)+(MaxLikelihoodSolver!$A14-1)*(94-36)) -> 0.0027174354 | H14: =INDEX(F:F,ROW($F$34)+(MaxLikelihoodSolver!$A14-1)*(94-36)) -> 0.12825834 | K14: =K899/$CJ5 -> -0.001463119 | L14: =L899*$CJ5 -> 0 | M14: =SQRT(Q19)/$CJ5 -> 0.00050345617 | O14: =B918 -> -0.18575442 | P14: =C918 -> -0.18575442 | Q14: =D918 -> -0.18575442 | R14: =E918 -> -78.323497
A15: 4 | B15: =INDEX(B:B,ROW($B$34)+(MaxLikelihoodSolver!$A15-1)*(94-36)) -> -0.67875783 | C15: =INDEX(B:B,ROW($B$35)+(MaxLikelihoodSolver!$A15-1)*(94-36)) -> 0.62598953 | D15: =INDEX(B:B,ROW($B$36)+(MaxLikelihoodSolver!$A15-1)*(94-36)) -> -0.34994318 | E15: =INDEX(B:B,ROW($B$37)+(MaxLikelihoodSolver!$A15-1)*(94-36)) -> 0.36219542 | F15: =INDEX(F:F,ROW($F$36)+(MaxLikelihoodSolver!$A15-1)*(94-36)) -> -487.23854 | G15: =INDEX(H:H,ROW($H$85)+(MaxLikelihoodSolver!$A15-1)*(94-36)) -> 0.0014330226 | H15: =INDEX(F:F,ROW($F$34)+(MaxLikelihoodSolver!$A15-1)*(94-36)) -> 0.064612432 | K15: =K900/$CJ6 -> 0.080732285 | L15: =L900*$CJ6 -> 0 | M15: =SQRT(R20)/$CJ6 -> 0.025109421
A16: 5 | B16: =INDEX(B:B,ROW($B$34)+(MaxLikelihoodSolver!$A16-1)*(94-36)) -> -0.67929939 | C16: =INDEX(B:B,ROW($B$35)+(MaxLikelihoodSolver!$A16-1)*(94-36)) -> 0.62562364 | D16: =INDEX(B:B,ROW($B$36)+(MaxLikelihoodSolver!$A16-1)*(94-36)) -> -0.35137621 | E16: =INDEX(B:B,ROW($B$37)+(MaxLikelihoodSolver!$A16-1)*(94-36)) -> 0.36262692 | F16: =INDEX(F:F,ROW($F$36)+(MaxLikelihoodSolver!$A16-1)*(94-36)) -> -487.23845 | G16: =INDEX(H:H,ROW($H$85)+(MaxLikelihoodSolver!$A16-1)*(94-36)) -> 0.0026085489 | H16: =INDEX(F:F,ROW($F$34)+(MaxLikelihoodSolver!$A16-1)*(94-36)) -> 0.054167332 | O16: Sigma -- scaled
A17: 6 | B17: =INDEX(B:B,ROW($B$34)+(MaxLikelihoodSolver!$A17-1)*(94-36)) -> -0.68166306 | C17: =INDEX(B:B,ROW($B$35)+(MaxLikelihoodSolver!$A17-1)*(94-36)) -> 0.62823218 | D17: =INDEX(B:B,ROW($B$36)+(MaxLikelihoodSolver!$A17-1)*(94-36)) -> -0.35115026 | E17: =INDEX(B:B,ROW($B$37)+(MaxLikelihoodSolver!$A17-1)*(94-36)) -> 0.36328263 | F17: =INDEX(F:F,ROW($F$36)+(MaxLikelihoodSolver!$A17-1)*(94-36)) -> -487.23803 | G17: =INDEX(H:H,ROW($H$85)+(MaxLikelihoodSolver!$A17-1)*(94-36)) -> 1.0189644e-05 | H17: =INDEX(F:F,ROW($F$34)+(MaxLikelihoodSolver!$A17-1)*(94-36)) -> 2.2707399e-06 | O17: {=-MINVERSE(O11:R14)} -> 0.01884705 | P17: 0.00011983124 | Q17: 0.00012483421 | R17: 0.00010999999
A18: 7 | B18: =INDEX(B:B,ROW($B$34)+(MaxLikelihoodSolver!$A18-1)*(94-36)) -> -0.68167325 | C18: =INDEX(B:B,ROW($B$35)+(MaxLikelihoodSolver!$A18-1)*(94-36)) -> 0.62822909 | D18: =INDEX(B:B,ROW($B$36)+(MaxLikelihoodSolver!$A18-1)*(94-36)) -> -0.35114938 | E18: =INDEX(B:B,ROW($B$37)+(MaxLikelihoodSolver!$A18-1)*(94-36)) -> 0.36328929 | F18: =INDEX(F:F,ROW($F$36)+(MaxLikelihoodSolver!$A18-1)*(94-36)) -> -487.23803 | G18: =INDEX(H:H,ROW($H$85)+(MaxLikelihoodSolver!$A18-1)*(94-36)) -> 9.3537748e-06 | H18: =INDEX(F:F,ROW($F$34)+(MaxLikelihoodSolver!$A18-1)*(94-36)) -> 5.173549e-07 | O18: -8.6346212e-05 | P18: 0.013877304 | Q18: -6.7111493e-05 | R18: -5.9136542e-05
A19: 8 | B19: =INDEX(B:B,ROW($B$34)+(MaxLikelihoodSolver!$A19-1)*(94-36)) -> -0.68168261 | C19: =INDEX(B:B,ROW($B$35)+(MaxLikelihoodSolver!$A19-1)*(94-36)) -> 0.62822622 | D19: =INDEX(B:B,ROW($B$36)+(MaxLikelihoodSolver!$A19-1)*(94-36)) -> -0.35114856 | E19: =INDEX(B:B,ROW($B$37)+(MaxLikelihoodSolver!$A19-1)*(94-36)) -> 0.36329527 | F19: =INDEX(F:F,ROW($F$36)+(MaxLikelihoodSolver!$A19-1)*(94-36)) -> -487.23803 | G19: =INDEX(H:H,ROW($H$85)+(MaxLikelihoodSolver!$A19-1)*(94-36)) -> 3.6538183e-08 | H19: =INDEX(F:F,ROW($F$34)+(MaxLikelihoodSolver!$A19-1)*(94-36)) -> 3.4149542e-12 | O19: 9.7741071e-05 | P19: 7.2923436e-05 | Q19: 0.014599763 | R19: 6.694062e-05
A20: 9 | B20: =INDEX(B:B,ROW($B$34)+(MaxLikelihoodSolver!$A20-1)*(94-36)) -> -0.68168264 | C20: =INDEX(B:B,ROW($B$35)+(MaxLikelihoodSolver!$A20-1)*(94-36)) -> 0.62822621 | D20: =INDEX(B:B,ROW($B$36)+(MaxLikelihoodSolver!$A20-1)*(94-36)) -> -0.35114855 | E20: =INDEX(B:B,ROW($B$37)+(MaxLikelihoodSolver!$A20-1)*(94-36)) -> 0.36329529 | F20: =INDEX(F:F,ROW($F$36)+(MaxLikelihoodSolver!$A20-1)*(94-36)) -> -487.23803 | G20: =INDEX(H:H,ROW($H$85)+(MaxLikelihoodSolver!$A20-1)*(94-36)) -> 1.1560909e-08 | H20: =INDEX(F:F,ROW($F$34)+(MaxLikelihoodSolver!$A20-1)*(94-36)) -> 7.5132214e-13 | O20: -4.472527e-05 | P20: -3.3368985e-05 | Q20: -3.4762146e-05 | R20: 0.012767281
A21: 10 | B21: =INDEX(B:B,ROW($B$34)+(MaxLikelihoodSolver!$A21-1)*(94-36)) -> -0.68168263 | C21: =INDEX(B:B,ROW($B$35)+(MaxLikelihoodSolver!$A21-1)*(94-36)) -> 0.62822621 | D21: =INDEX(B:B,ROW($B$36)+(MaxLikelihoodSolver!$A21-1)*(94-36)) -> -0.35114856 | E21: =INDEX(B:B,ROW($B$37)+(MaxLikelihoodSolver!$A21-1)*(94-36)) -> 0.36329528 | F21: =INDEX(F:F,ROW($F$36)+(MaxLikelihoodSolver!$A21-1)*(94-36)) -> -487.23803 | G21: =INDEX(H:H,ROW($H$85)+(MaxLikelihoodSolver!$A21-1)*(94-36)) -> 1.3547941e-10 | H21: =INDEX(F:F,ROW($F$34)+(MaxLikelihoodSolver!$A21-1)*(94-36)) -> 5.2544169e-17
A22: 11 | B22: =INDEX(B:B,ROW($B$34)+(MaxLikelihoodSolver!$A22-1)*(94-36)) -> -0.68168263 | C22: =INDEX(B:B,ROW($B$35)+(MaxLikelihoodSolver!$A22-1)*(94-36)) -> 0.62822621 | D22: =INDEX(B:B,ROW($B$36)+(MaxLikelihoodSolver!$A22-1)*(94-36)) -> -0.35114856 | E22: =INDEX(B:B,ROW($B$37)+(MaxLikelihoodSolver!$A22-1)*(94-36)) -> 0.36329528 | F22: =INDEX(F:F,ROW($F$36)+(MaxLikelihoodSolver!$A22-1)*(94-36)) -> -487.23803 | G22: =INDEX(H:H,ROW($H$85)+(MaxLikelihoodSolver!$A22-1)*(94-36)) -> 3.7574367e-11 | H22: =INDEX(F:F,ROW($F$34)+(MaxLikelihoodSolver!$A22-1)*(94-36)) -> 8.0227551e-18
A23: 12 | B23: =INDEX(B:B,ROW($B$34)+(MaxLikelihoodSolver!$A23-1)*(94-36)) -> -0.68168263 | C23: =INDEX(B:B,ROW($B$35)+(MaxLikelihoodSolver!$A23-1)*(94-36)) -> 0.62822621 | D23: =INDEX(B:B,ROW($B$36)+(MaxLikelihoodSolver!$A23-1)*(94-36)) -> -0.35114856 | E23: =INDEX(B:B,ROW($B$37)+(MaxLikelihoodSolver!$A23-1)*(94-36)) -> 0.36329528 | F23: =INDEX(F:F,ROW($F$36)+(MaxLikelihoodSolver!$A23-1)*(94-36)) -> -487.23803 | G23: =INDEX(H:H,ROW($H$85)+(MaxLikelihoodSolver!$A23-1)*(94-36)) -> 4.4032461e-13 | H23: =INDEX(F:F,ROW($F$34)+(MaxLikelihoodSolver!$A23-1)*(94-36)) -> 1.3412024e-21
A24: 13 | B24: =INDEX(B:B,ROW($B$34)+(MaxLikelihoodSolver!$A24-1)*(94-36)) -> -0.68168263 | C24: =INDEX(B:B,ROW($B$35)+(MaxLikelihoodSolver!$A24-1)*(94-36)) -> 0.62822621 | D24: =INDEX(B:B,ROW($B$36)+(MaxLikelihoodSolver!$A24-1)*(94-36)) -> -0.35114856 | E24: =INDEX(B:B,ROW($B$37)+(MaxLikelihoodSolver!$A24-1)*(94-36)) -> 0.36329528 | F24: =INDEX(F:F,ROW($F$36)+(MaxLikelihoodSolver!$A24-1)*(94-36)) -> -487.23803 | G24: =INDEX(H:H,ROW($H$85)+(MaxLikelihoodSolver!$A24-1)*(94-36)) -> 5.3320558e-14 | H24: =INDEX(F:F,ROW($F$34)+(MaxLikelihoodSolver!$A24-1)*(94-36)) -> 1.506193e-23
A25: 14 | B25: =INDEX(B:B,ROW($B$34)+(MaxLikelihoodSolver!$A25-1)*(94-36)) -> -0.68168263 | C25: =INDEX(B:B,ROW($B$35)+(MaxLikelihoodSolver!$A25-1)*(94-36)) -> 0.62822621 | D25: =INDEX(B:B,ROW($B$36)+(MaxLikelihoodSolver!$A25-1)*(94-36)) -> -0.35114856 | E25: =INDEX(B:B,ROW($B$37)+(MaxLikelihoodSolver!$A25-1)*(94-36)) -> 0.36329528 | F25: =INDEX(F:F,ROW($F$36)+(MaxLikelihoodSolver!$A25-1)*(94-36)) -> -487.23803 | G25: =INDEX(H:H,ROW($H$85)+(MaxLikelihoodSolver!$A25-1)*(94-36)) -> 3.5408183e-15 | H25: =INDEX(F:F,ROW($F$34)+(MaxLikelihoodSolver!$A25-1)*(94-36)) -> 3.3977817e-26
A26: 15 | B26: =INDEX(B:B,ROW($B$34)+(MaxLikelihoodSolver!$A26-1)*(94-36)) -> -0.68168263 | C26: =INDEX(B:B,ROW($B$35)+(MaxLikelihoodSolver!$A26-1)*(94-36)) -> 0.62822621 | D26: =INDEX(B:B,ROW($B$36)+(MaxLikelihoodSolver!$A26-1)*(94-36)) -> -0.35114856 | E26: =INDEX(B:B,ROW($B$37)+(MaxLikelihoodSolver!$A26-1)*(94-36)) -> 0.36329528 | F26: =INDEX(F:F,ROW($F$36)+(MaxLikelihoodSolver!$A26-1)*(94-36)) -> -487.23803 | G26: =INDEX(H:H,ROW($H$85)+(MaxLikelihoodSolver!$A26-1)*(94-36)) -> 2.0608669e-15 | H26: =INDEX(F:F,ROW($F$34)+(MaxLikelihoodSolver!$A26-1)*(94-36)) -> 1.0160528e-26
A30: BFGS Optimization of Maximum Likelihood using Analytical Gradients and Bisection Line Search
A32: BFGS Iteration | C32: 1
B33: beta | D33: gradient | F33: NormGradient | H33: inv(B_k) | M33: p_k_unnorm | N33: p_k | P33: grad_k+1 | R33: s_k | T33: y_k | V33: Binv*y | X33: Inv(B_k+1) | AC33: Sum
B34: 0 | D34: =$CE$3-$CE$7*SUMPRODUCT($B$3:$CD$3,AE36:DG36) -> -47.333333 | F34: =SUMPRODUCT(D34:D37,D34:D37) -> 6287.3349 | H34: 1 | I34: 0 | J34: 0 | K34: 0 | M34: {=MMULT(H34:K37,D34:D37)} -> -47.333333 | N34: =IFERROR(M34/(MAX(ABS(M34),ABS(M35),ABS(M36),ABS(M37))),0) -> -0.95761079 | P34: =L85 -> -3.1281693 | R34: =H85*J85 -> -0.62469141 | T34: =P34-D34 -> 44.205164 | V34: {=MMULT(H34:K37,T34:T37)} -> 44.205164 | X34: {=H34:K37+MMULT(R34:R37,TRANSPOSE(R34:R37))*((SUMPRODUCT(R34:R37,T34:T37)+SUMPRODUCT(V34:V37,T34:T37))/SUMPRODUCT(R34:R37,T34:T37)^2)-(MMULT(V34:V37,TRANSPOSE(R34:R37))+MMULT(R34:R37,TRANSPOSE(V34:V37)))/SUMPRODUCT(R34:R37,T34:T37)} -> 0.68765892 | Y34: 0.36366429 | Z34: -0.20120758 | AA34: 0.21881568 | AC34: =SUM(AE34:DG34) -> 0 | AD34: v_j | AE34: =SUMPRODUCT(B$3:B$6,$B34:$B37) -> 0 | AF34: =SUMPRODUCT(C$3:C$6,$B34:$B37) -> 0 | AG34: =SUMPRODUCT(D$3:D$6,$B34:$B37) -> 0 | AH34: =SUMPRODUCT(E$3:E$6,$B34:$B37) -> 0 | AI34: =SUMPRODUCT(F$3:F$6,$B34:$B37) -> 0 | AJ34: =SUMPRODUCT(G$3:G$6,$B34:$B37) -> 0 | AK34: =SUMPRODUCT(H$3:H$6,$B34:$B37) -> 0 | AL34: =SUMPRODUCT(I$3:I$6,$B34:$B37) -> 0 | ... DG34: =SUMPRODUCT(CD$3:CD$6,$B34:$B37) -> 0
B35: 0 | D35: =$CE$4-$CE$7*SUMPRODUCT($B$4:$CD$4,AE36:DG36) -> 49.428571 | F35: LogLikelihood | H35: 0 | I35: 1 | J35: 0 | K35: 0 | M35: 49.428571 | N35: =IFERROR(M35/(MAX(ABS(M34),ABS(M35),ABS(M36),ABS(M37))),0) -> 1 | P35: =L86 -> -1.7193428 | R35: =H86*J86 -> 0.65234375 | T35: =P35-D35 -> -51.147914 | V35: -51.147914 | X35: 0.36366429 | Y35: 0.58108082 | Z35: 0.23189952 | AA35: -0.25156337 | AC35: =SUM(AE35:DG35) -> 81 | AD35: exp(v_j) | AE35: =EXP(AE34) -> 1 | AF35: =EXP(AF34) -> 1 | AG35: =EXP(AG34) -> 1 | AH35: =EXP(AH34) -> 1 | AI35: =EXP(AI34) -> 1 | AJ35: =EXP(AJ34) -> 1 | AK35: =EXP(AK34) -> 1 | AL35: =EXP(AL34) -> 1 | ... DG35: =EXP(DG34) -> 1
B36: 0 | D36: =$CE$5-$CE$7*SUMPRODUCT($B$5:$CD$5,AE36:DG36) -> -27.5 | F36: =SUMPRODUCT($B$7:$CD$7, LN(AE36:DG36)) -> -527.3339 | H36: 0 | I36: 0 | J36: 1 | K36: 0 | M36: -27.5 | N36: =IFERROR(M36/(MAX(ABS(M34),ABS(M35),ABS(M36),ABS(M37))),0) -> -0.55635838 | P36: =L87 -> 0.80763277 | R36: =H87*J87 -> -0.36293691 | T36: =P36-D36 -> 28.307633 | V36: 28.307633 | X36: -0.20120758 | Y36: 0.23189952 | Z36: 0.87163151 | AA36: 0.13927051 | AC36: =SUM(AE36:DG36) -> 1 | AD36: P_j | AE36: =AE35/$AC35 -> 0.012345679 | AF36: =AF35/$AC35 -> 0.012345679 | AG36: =AG35/$AC35 -> 0.012345679 | AH36: =AH35/$AC35 -> 0.012345679 | AI36: =AI35/$AC35 -> 0.012345679 | AJ36: =AJ35/$AC35 -> 0.012345679 | AK36: =AK35/$AC35 -> 0.012345679 | AL36: =AL35/$AC35 -> 0.012345679 | ... DG36: =DG35/$AC35 -> 0.012345679
B37: 0 | D37: =$CE$6-$CE$7*SUMPRODUCT($B$6:$CD$6,AE36:DG36) -> 29.111111 | H37: 0 | I37: 0 | J37: 0 | K37: 1 | M37: 29.111111 | N37: =IFERROR(M37/(MAX(ABS(M34),ABS(M35),ABS(M36),ABS(M37))),0) -> 0.58895311 | P37: =L88 -> -1.6288544 | R37: =H88*J88 -> 0.38419988 | T37: =P37-D37 -> -30.739965 | V37: -30.739965 | X37: 0.21881568 | Y37: -0.25156337 | Z37: 0.13927051 | AA37: 0.84899066
B39: LineSearch Iteration | D39: low | E39: high | F39: bracket? | H39: alpha | I39: beta_iter | J39: p_k_iter | K39: beta | L39: gradient | M39: derivative
B40: 1 | D40: 0 | F40: FALSE | H40: 0 | I40: =B34 -> 0 | J40: =IF(SUMPRODUCT(L40:L43,N34:N37)>0,N34,-N34) -> -0.95761079 | K40: =I40+J40*H40 -> 0 | L40: =D34 -> -47.333333 | M40: =SUMPRODUCT(L40:L43,J40:J43) -> 127.20042
H41: =H40 -> 0 | I41: =B35 -> 0 | J41: =IF(SUMPRODUCT(L40:L43,N34:N37)>0,N35,-N35) -> 1 | K41: =I41+J41*H41 -> 0 | L41: =D35 -> 49.428571 | M41: ln(likelihood)
H42: =H41 -> 0 | I42: =B36 -> 0 | J42: =IF(SUMPRODUCT(L40:L43,N34:N37)>0,N36,-N36) -> -0.55635838 | K42: =I42+J42*H42 -> 0 | L42: =D36 -> -27.5 | M42: =F36 -> -527.3339
H43: =H42 -> 0 | I43: =B37 -> 0 | J43: =IF(SUMPRODUCT(L40:L43,N34:N37)>0,N37,-N37) -> 0.58895311 | K43: =I43+J43*H43 -> 0 | L43: =D37 -> 29.111111
B44: LineSearch Iteration | D44: low | E44: high | F44: bracket? | H44: alpha | I44: beta_iter | J44: p_k_iter | K44: beta | L44: gradient | M44: derivative | O44: Sum
B45: =1+B40 -> 2 | D45: 0 | E45: =H45 -> 1 | F45: =OR(F40,M45*M40<=0) -> TRUE | H45: 1 | I45: =I40 -> 0 | J45: =J40 -> -0.95761079 | K45: =I45+J45*H45 -> -0.95761079 | L45: =$CE$3-$CE$7*SUMPRODUCT($B$3:$CD$3,Q47:CS47) -> 13.014311 | M45: =SUMPRODUCT(L45:L48,J45:J48) -> -53.518572 | O45: =SUM(Q45:CS45) -> 10.505333 | P45: v_j | Q45: =SUMPRODUCT(B$3:B$6,$K45:$K48) -> -0.074983943 | R45: =SUMPRODUCT(C$3:C$6,$K45:$K48) -> 0.44852994 | S45: =SUMPRODUCT(D$3:D$6,$K45:$K48) -> 1.1029223 | T45: =SUMPRODUCT(E$3:E$6,$K45:$K48) -> -0.35316313 | U45: =SUMPRODUCT(F$3:F$6,$K45:$K48) -> 0.17035075 | V45: =SUMPRODUCT(G$3:G$6,$K45:$K48) -> 0.8247431 | W45: =SUMPRODUCT(H$3:H$6,$K45:$K48) -> -1.1877007 | X45: =SUMPRODUCT(I$3:I$6,$K45:$K48) -> -0.66418683 | ... CS45: =SUMPRODUCT(CD$3:CD$6,$K45:$K48) -> 0.074983943
H46: =H45 -> 1 | I46: =I41 -> 0 | J46: =J41 -> 1 | K46: =I46+J46*H46 -> 1 | L46: =$CE$4-$CE$7*SUMPRODUCT($B$4:$CD$4,Q47:CS47) -> -23.87612 | M46: ln(likelihood) | O46: =SUM(Q46:CS46) -> 206.78854 | P46: exp(v_j) | Q46: =EXP(Q45) -> 0.92775838 | R46: =EXP(R45) -> 1.5660084 | S46: =EXP(S45) -> 3.0129579 | T46: =EXP(T45) -> 0.70246259 | U46: =EXP(U45) -> 1.1857207 | V46: =EXP(V45) -> 2.2812946 | W46: =EXP(W45) -> 0.30492156 | X46: =EXP(X45) -> 0.51469189 | ... CS46: =EXP(CS45) -> 1.0778668
...

Sheet PredictionSolver
A1: exp(v) competition
A2: competitor 1 | B2: competitor 2 | C2: competitor 3 | D2: competitor 4 | E2: Total exp_vc
A3: =IF(ISBLANK(DemandPredictionModel!C12),0,EXP(SUMPRODUCT(DemandPredictionModel!C12:C15,MaxLikelihoodSolver!$K$12:$K$15))) -> 0.38960146 | B3: =IF(ISBLANK(DemandPredictionModel!D12),0,EXP(SUMPRODUCT(DemandPredictionModel!D12:D15,MaxLikelihoodSolver!$K$12:$K$15))) -> 0.37106846 | C3: =IF(ISBLANK(DemandPredictionModel!E12),0,EXP(SUMPRODUCT(DemandPredictionModel!E12:E15,MaxLikelihoodSolver!$K$12:$K$15))) -> 0.9970298 | D3: =IF(ISBLANK(DemandPredictionModel!F12),0,EXP(SUMPRODUCT(DemandPredictionModel!F12:F15,MaxLikelihoodSolver!$K$12:$K$15))) -> 0.6216273 | E3: =SUM(A3:D3) -> 2.379327
A6: Solving for max profit using Haley's algorithm and the Lambeth function
A7: =SUMPRODUCT(DemandPredictionModel!$C$6:$C$8,DemandPredictionModel!$C$24:$C$26) -> 0.86221078 | C7: beta1*xin1+..+beta3+xin3
A8: =EXP($A$7+marginalCost*DemandPredictionModel!$C$5-1)/PredictionSolver!$E$3 -> 0.28650117 | C8: argument for Lambeth function
A9: 1 | C9: initial guess for W_1
A10: =A9 - (A9*EXP(A9)-$A$8)/((EXP(A9)*(A9+1) - (A9+2)*(A9*EXP(A9)-$A$8)/(2*A9+2))) -> 0.32688524 | C10: guess 1
A11: =A10 - (A10*EXP(A10)-$A$8)/((EXP(A10)*(A10+1) - (A10+2)*(A10*EXP(A10)-$A$8)/(2*A10+2))) -> 0.2284185 | C11: guess 2
A12: =A11 - (A11*EXP(A11)-$A$8)/((EXP(A11)*(A11+1) - (A11+2)*(A11*EXP(A11)-$A$8)/(2*A11+2))) -> 0.22807372 | C12: guess 3
A13: =A12 - (A12*EXP(A12)-$A$8)/((EXP(A12)*(A12+1) - (A12+2)*(A12*EXP(A12)-$A$8)/(2*A12+2))) -> 0.22807372 | C13: guess 4
A14: =A13 - (A13*EXP(A13)-$A$8)/((EXP(A13)*(A13+1) - (A13+2)*(A13*EXP(A13)-$A$8)/(2*A13+2))) -> 0.22807372 | C14: guess 5
A15: =A14 - (A14*EXP(A14)-$A$8)/((EXP(A14)*(A14+1) - (A14+2)*(A14*EXP(A14)-$A$8)/(2*A14+2))) -> 0.22807372 | C15: guess 6
A16: =A15 - (A15*EXP(A15)-$A$8)/((EXP(A15)*(A15+1) - (A15+2)*(A15*EXP(A15)-$A$8)/(2*A15+2))) -> 0.22807372 | C16: guess 7
A17: =A16 - (A16*EXP(A16)-$A$8)/((EXP(A16)*(A16+1) - (A16+2)*(A16*EXP(A16)-$A$8)/(2*A16+2))) -> 0.22807372 | C17: guess 8
A18: =A17 - (A17*EXP(A17)-$A$8)/((EXP(A17)*(A17+1) - (A17+2)*(A17*EXP(A17)-$A$8)/(2*A17+2))) -> 0.22807372 | C18: guess 9
A19: =A18 - (A18*EXP(A18)-$A$8)/((EXP(A18)*(A18+1) - (A18+2)*(A18*EXP(A18)-$A$8)/(2*A18+2))) -> 0.22807372 | C19: guess 10
A20: =A19 - (A19*EXP(A19)-$A$8)/((EXP(A19)*(A19+1) - (A19+2)*(A19*EXP(A19)-$A$8)/(2*A19+2))) -> 0.22807372 | C20: guess 11
A21: =A20 - (A20*EXP(A20)-$A$8)/((EXP(A20)*(A20+1) - (A20+2)*(A20*EXP(A20)-$A$8)/(2*A20+2))) -> 0.22807372 | C21: guess 12
... A131: =A130 - (A130*EXP(A130)-$A$8)/((EXP(A130)*(A130+1) - (A130+2)*(A130*EXP(A130)-$A$8)/(2*A130+2))) -> 0.22807372 | C131: guess 122 — should have definitely converged at this point
A132: =-(A131-DemandPredictionModel!$C$5*marginalCost+1)/DemandPredictionModel!$C$5 -> 162.11497 | C132: price assuming capacity constraint is NOT active
A133: =EXP($A$7+$A$132*DemandPredictionModel!$C$5)/(EXP($A$7+$A$132*DemandPredictionModel!$C$5)+PredictionSolver!$E$3)*marketSize -> 3714.3327 | C133: demand
A134: =($A$132-marginalCost)*$A$133 -> 501861.95 | C134: profit
A136: Solving for price to meet capacity constraint
A137: =IFERROR(MAX((-$A$7+LN($E$3*capacity/(marketSize-capacity)))/DemandPredictionModel!$C$5,0),0) -> 0 | C137: price assuming capacity constraint is active (cap at min of zero)
A138: =EXP($A$7+A137*DemandPredictionModel!$C$5)/(EXP($A$7+$A$137*DemandPredictionModel!C5)+$E$3)*marketSize -> 9976.9655 | C138: demand
A139: =($A$137-marginalCost)*$A$138 -> -269378.07 | C139: profit

Sheet StaticRandomNumbers
A1: Random numbers (These numbers are static -- to replace them, paste here by value from the table on the next tab "RandomNumbersToCopyFrom")
B2: Student ID
A3: Option | B3: 1 | C3: 2 | D3: 3 | E3: 4 | F3: 5 | G3: 6 | H3: 7 | I3: 8 | J3: 9 | K3: 10 | L3: 11 | M3: 12 | N3: 13 | O3: 14 | P3: 15 | Q3: 16 | R3: 17 | S3: 18 | T3: 19 | U3: 20 | V3: 21 | W3: 22 | X3: 23 | Y3: 24 | Z3: 25 | AA3: 26 | AB3: 27 | AC3: 28 | AD3: 29 | AE3: 30 | AF3: 31 | AG3: 32 | AH3: 33 | AI3: 34 | AJ3: 35 | AK3: 36 | AL3: 37 | AM3: 38 | AN3: 39 | AO3: 40 | AP3: 41 | AQ3: 42 | AR3: 43 | AS3: 44 | AT3: 45 | AU3: 46 | AV3: 47 | AW3: 48 | AX3: 49 | AY3: 50 | AZ3: 51 | BA3: 52 | BB3: 53 | BC3: 54 | BD3: 55 | BE3: 56 | BF3: 57 | BG3: 58 | BH3: 59 | BI3: 60 | BJ3: Validity test
A4: 1 | B4: 11 | C4: 81 | D4: 37 | E4: 73 | F4: 46 | G4: 45 | H4: 69 | I4: 74 | J4: 55 | K4: 63 | L4: 6 | M4: 44 | N4: 71 | O4: 19 | P4: 72 | Q4: 73 | R4: 58 | S4: 3 | T4: 41 | U4: 7 | V4: 19 | W4: 73 | X4: 35 | Y4: 73 | Z4: 18 | AA4: 48 | AB4: 19 | AC4: 16 | AD4: 55 | AE4: 64 | AF4: 21 | AG4: 29 | AH4: 56 | AI4: 30 | AJ4: 7 | AK4: 36 | AL4: 23 | AM4: 66 | AN4: 41 | AO4: 56 | AP4: 24 | AQ4: 79 | AR4: 3 | AS4: 81 | AT4: 46 | AU4: 48 | AV4: 52 | AW4: 53 | AX4: 13 | AY4: 2 | AZ4: 65 | BA4: 58 | BB4: 62 | BC4: 75 | BD4: 63 | BE4: 13 | BF4: 60 | BG4: 17 | BH4: 18 | BI4: 1 | BJ4: =OR(B96:BI96) -> FALSE
